2021-02-08 16:24:48,528 Session data corrupted
2021-02-08 16:24:48,740 Session data corrupted
2021-02-08 16:24:56,215 Not Found: /favicon.ico
2021-02-08 16:26:24,201 Session data corrupted
2021-02-08 16:26:31,682 Session data corrupted
2021-02-08 16:26:36,491 Internal Server Error: /admin/api/transaction/
Traceback (most recent call last):
  File "C:\Users\User\AppData\Local\Programs\Python\Python38-32\lib\site-packages\django\db\backends\utils.py", line 84, in _execute
    return self.cursor.execute(sql, params)
psycopg2.errors.UndefinedTable: relation "api_transaction" does not exist
LINE 1: SELECT COUNT(*) AS "__count" FROM "api_transaction"
                                          ^


The above exception was the direct cause of the following exception:

Traceback (most recent call last):
  File "C:\Users\User\AppData\Local\Programs\Python\Python38-32\lib\site-packages\django\core\handlers\exception.py", line 47, in inner
    response = get_response(request)
  File "C:\Users\User\AppData\Local\Programs\Python\Python38-32\lib\site-packages\django\core\handlers\base.py", line 179, in _get_response
    response = wrapped_callback(request, *callback_args, **callback_kwargs)
  File "C:\Users\User\AppData\Local\Programs\Python\Python38-32\lib\site-packages\django\contrib\admin\options.py", line 614, in wrapper
    return self.admin_site.admin_view(view)(*args, **kwargs)
  File "C:\Users\User\AppData\Local\Programs\Python\Python38-32\lib\site-packages\django\utils\decorators.py", line 130, in _wrapped_view
    response = view_func(request, *args, **kwargs)
  File "C:\Users\User\AppData\Local\Programs\Python\Python38-32\lib\site-packages\django\views\decorators\cache.py", line 44, in _wrapped_view_func
    response = view_func(request, *args, **kwargs)
  File "C:\Users\User\AppData\Local\Programs\Python\Python38-32\lib\site-packages\django\contrib\admin\sites.py", line 233, in inner
    return view(request, *args, **kwargs)
  File "C:\Users\User\AppData\Local\Programs\Python\Python38-32\lib\site-packages\django\utils\decorators.py", line 43, in _wrapper
    return bound_method(*args, **kwargs)
  File "C:\Users\User\AppData\Local\Programs\Python\Python38-32\lib\site-packages\django\utils\decorators.py", line 130, in _wrapped_view
    response = view_func(request, *args, **kwargs)
  File "C:\Users\User\AppData\Local\Programs\Python\Python38-32\lib\site-packages\django\contrib\admin\options.py", line 1693, in changelist_view
    cl = self.get_changelist_instance(request)
  File "C:\Users\User\AppData\Local\Programs\Python\Python38-32\lib\site-packages\django\contrib\admin\options.py", line 735, in get_changelist_instance
    return ChangeList(
  File "C:\Users\User\AppData\Local\Programs\Python\Python38-32\lib\site-packages\django\contrib\admin\views\main.py", line 100, in __init__
    self.get_results(request)
  File "C:\Users\User\AppData\Local\Programs\Python\Python38-32\lib\site-packages\django\contrib\admin\views\main.py", line 235, in get_results
    result_count = paginator.count
  File "C:\Users\User\AppData\Local\Programs\Python\Python38-32\lib\site-packages\django\utils\functional.py", line 48, in __get__
    res = instance.__dict__[self.name] = self.func(instance)
  File "C:\Users\User\AppData\Local\Programs\Python\Python38-32\lib\site-packages\django\core\paginator.py", line 94, in count
    return c()
  File "C:\Users\User\AppData\Local\Programs\Python\Python38-32\lib\site-packages\django\db\models\query.py", line 411, in count
    return self.query.get_count(using=self.db)
  File "C:\Users\User\AppData\Local\Programs\Python\Python38-32\lib\site-packages\django\db\models\sql\query.py", line 515, in get_count
    number = obj.get_aggregation(using, ['__count'])['__count']
  File "C:\Users\User\AppData\Local\Programs\Python\Python38-32\lib\site-packages\django\db\models\sql\query.py", line 500, in get_aggregation
    result = compiler.execute_sql(SINGLE)
  File "C:\Users\User\AppData\Local\Programs\Python\Python38-32\lib\site-packages\django\db\models\sql\compiler.py", line 1156, in execute_sql
    cursor.execute(sql, params)
  File "C:\Users\User\AppData\Local\Programs\Python\Python38-32\lib\site-packages\django\db\backends\utils.py", line 98, in execute
    return super().execute(sql, params)
  File "C:\Users\User\AppData\Local\Programs\Python\Python38-32\lib\site-packages\django\db\backends\utils.py", line 66, in execute
    return self._execute_with_wrappers(sql, params, many=False, executor=self._execute)
  File "C:\Users\User\AppData\Local\Programs\Python\Python38-32\lib\site-packages\django\db\backends\utils.py", line 75, in _execute_with_wrappers
    return executor(sql, params, many, context)
  File "C:\Users\User\AppData\Local\Programs\Python\Python38-32\lib\site-packages\django\db\backends\utils.py", line 84, in _execute
    return self.cursor.execute(sql, params)
  File "C:\Users\User\AppData\Local\Programs\Python\Python38-32\lib\site-packages\django\db\utils.py", line 90, in __exit__
    raise dj_exc_value.with_traceback(traceback) from exc_value
  File "C:\Users\User\AppData\Local\Programs\Python\Python38-32\lib\site-packages\django\db\backends\utils.py", line 84, in _execute
    return self.cursor.execute(sql, params)
django.db.utils.ProgrammingError: relation "api_transaction" does not exist
LINE 1: SELECT COUNT(*) AS "__count" FROM "api_transaction"
                                          ^

2021-02-08 16:34:57,756 Internal Server Error: /admin/api/transaction/
Traceback (most recent call last):
  File "C:\Users\User\AppData\Local\Programs\Python\Python38-32\lib\site-packages\django\db\backends\utils.py", line 84, in _execute
    return self.cursor.execute(sql, params)
psycopg2.errors.UndefinedTable: relation "api_transaction" does not exist
LINE 1: SELECT COUNT(*) AS "__count" FROM "api_transaction"
                                          ^


The above exception was the direct cause of the following exception:

Traceback (most recent call last):
  File "C:\Users\User\AppData\Local\Programs\Python\Python38-32\lib\site-packages\django\core\handlers\exception.py", line 47, in inner
    response = get_response(request)
  File "C:\Users\User\AppData\Local\Programs\Python\Python38-32\lib\site-packages\django\core\handlers\base.py", line 179, in _get_response
    response = wrapped_callback(request, *callback_args, **callback_kwargs)
  File "C:\Users\User\AppData\Local\Programs\Python\Python38-32\lib\site-packages\django\contrib\admin\options.py", line 614, in wrapper
    return self.admin_site.admin_view(view)(*args, **kwargs)
  File "C:\Users\User\AppData\Local\Programs\Python\Python38-32\lib\site-packages\django\utils\decorators.py", line 130, in _wrapped_view
    response = view_func(request, *args, **kwargs)
  File "C:\Users\User\AppData\Local\Programs\Python\Python38-32\lib\site-packages\django\views\decorators\cache.py", line 44, in _wrapped_view_func
    response = view_func(request, *args, **kwargs)
  File "C:\Users\User\AppData\Local\Programs\Python\Python38-32\lib\site-packages\django\contrib\admin\sites.py", line 233, in inner
    return view(request, *args, **kwargs)
  File "C:\Users\User\AppData\Local\Programs\Python\Python38-32\lib\site-packages\django\utils\decorators.py", line 43, in _wrapper
    return bound_method(*args, **kwargs)
  File "C:\Users\User\AppData\Local\Programs\Python\Python38-32\lib\site-packages\django\utils\decorators.py", line 130, in _wrapped_view
    response = view_func(request, *args, **kwargs)
  File "C:\Users\User\AppData\Local\Programs\Python\Python38-32\lib\site-packages\django\contrib\admin\options.py", line 1693, in changelist_view
    cl = self.get_changelist_instance(request)
  File "C:\Users\User\AppData\Local\Programs\Python\Python38-32\lib\site-packages\django\contrib\admin\options.py", line 735, in get_changelist_instance
    return ChangeList(
  File "C:\Users\User\AppData\Local\Programs\Python\Python38-32\lib\site-packages\django\contrib\admin\views\main.py", line 100, in __init__
    self.get_results(request)
  File "C:\Users\User\AppData\Local\Programs\Python\Python38-32\lib\site-packages\django\contrib\admin\views\main.py", line 235, in get_results
    result_count = paginator.count
  File "C:\Users\User\AppData\Local\Programs\Python\Python38-32\lib\site-packages\django\utils\functional.py", line 48, in __get__
    res = instance.__dict__[self.name] = self.func(instance)
  File "C:\Users\User\AppData\Local\Programs\Python\Python38-32\lib\site-packages\django\core\paginator.py", line 94, in count
    return c()
  File "C:\Users\User\AppData\Local\Programs\Python\Python38-32\lib\site-packages\django\db\models\query.py", line 411, in count
    return self.query.get_count(using=self.db)
  File "C:\Users\User\AppData\Local\Programs\Python\Python38-32\lib\site-packages\django\db\models\sql\query.py", line 515, in get_count
    number = obj.get_aggregation(using, ['__count'])['__count']
  File "C:\Users\User\AppData\Local\Programs\Python\Python38-32\lib\site-packages\django\db\models\sql\query.py", line 500, in get_aggregation
    result = compiler.execute_sql(SINGLE)
  File "C:\Users\User\AppData\Local\Programs\Python\Python38-32\lib\site-packages\django\db\models\sql\compiler.py", line 1156, in execute_sql
    cursor.execute(sql, params)
  File "C:\Users\User\AppData\Local\Programs\Python\Python38-32\lib\site-packages\django\db\backends\utils.py", line 98, in execute
    return super().execute(sql, params)
  File "C:\Users\User\AppData\Local\Programs\Python\Python38-32\lib\site-packages\django\db\backends\utils.py", line 66, in execute
    return self._execute_with_wrappers(sql, params, many=False, executor=self._execute)
  File "C:\Users\User\AppData\Local\Programs\Python\Python38-32\lib\site-packages\django\db\backends\utils.py", line 75, in _execute_with_wrappers
    return executor(sql, params, many, context)
  File "C:\Users\User\AppData\Local\Programs\Python\Python38-32\lib\site-packages\django\db\backends\utils.py", line 84, in _execute
    return self.cursor.execute(sql, params)
  File "C:\Users\User\AppData\Local\Programs\Python\Python38-32\lib\site-packages\django\db\utils.py", line 90, in __exit__
    raise dj_exc_value.with_traceback(traceback) from exc_value
  File "C:\Users\User\AppData\Local\Programs\Python\Python38-32\lib\site-packages\django\db\backends\utils.py", line 84, in _execute
    return self.cursor.execute(sql, params)
django.db.utils.ProgrammingError: relation "api_transaction" does not exist
LINE 1: SELECT COUNT(*) AS "__count" FROM "api_transaction"
                                          ^

2021-02-08 16:46:26,255 C:\ES_POST_API\es_post_api\es_post_api\settings.py changed, reloading.
2021-02-08 16:47:08,499 Internal Server Error: /admin/api/transaction/
Traceback (most recent call last):
  File "C:\Users\User\AppData\Local\Programs\Python\Python38-32\lib\site-packages\django\db\backends\utils.py", line 84, in _execute
    return self.cursor.execute(sql, params)
psycopg2.errors.UndefinedTable: relation "api_transaction" does not exist
LINE 1: SELECT COUNT(*) AS "__count" FROM "api_transaction"
                                          ^


The above exception was the direct cause of the following exception:

Traceback (most recent call last):
  File "C:\Users\User\AppData\Local\Programs\Python\Python38-32\lib\site-packages\django\core\handlers\exception.py", line 47, in inner
    response = get_response(request)
  File "C:\Users\User\AppData\Local\Programs\Python\Python38-32\lib\site-packages\django\core\handlers\base.py", line 179, in _get_response
    response = wrapped_callback(request, *callback_args, **callback_kwargs)
  File "C:\Users\User\AppData\Local\Programs\Python\Python38-32\lib\site-packages\django\contrib\admin\options.py", line 614, in wrapper
    return self.admin_site.admin_view(view)(*args, **kwargs)
  File "C:\Users\User\AppData\Local\Programs\Python\Python38-32\lib\site-packages\django\utils\decorators.py", line 130, in _wrapped_view
    response = view_func(request, *args, **kwargs)
  File "C:\Users\User\AppData\Local\Programs\Python\Python38-32\lib\site-packages\django\views\decorators\cache.py", line 44, in _wrapped_view_func
    response = view_func(request, *args, **kwargs)
  File "C:\Users\User\AppData\Local\Programs\Python\Python38-32\lib\site-packages\django\contrib\admin\sites.py", line 233, in inner
    return view(request, *args, **kwargs)
  File "C:\Users\User\AppData\Local\Programs\Python\Python38-32\lib\site-packages\django\utils\decorators.py", line 43, in _wrapper
    return bound_method(*args, **kwargs)
  File "C:\Users\User\AppData\Local\Programs\Python\Python38-32\lib\site-packages\django\utils\decorators.py", line 130, in _wrapped_view
    response = view_func(request, *args, **kwargs)
  File "C:\Users\User\AppData\Local\Programs\Python\Python38-32\lib\site-packages\django\contrib\admin\options.py", line 1693, in changelist_view
    cl = self.get_changelist_instance(request)
  File "C:\Users\User\AppData\Local\Programs\Python\Python38-32\lib\site-packages\django\contrib\admin\options.py", line 735, in get_changelist_instance
    return ChangeList(
  File "C:\Users\User\AppData\Local\Programs\Python\Python38-32\lib\site-packages\django\contrib\admin\views\main.py", line 100, in __init__
    self.get_results(request)
  File "C:\Users\User\AppData\Local\Programs\Python\Python38-32\lib\site-packages\django\contrib\admin\views\main.py", line 235, in get_results
    result_count = paginator.count
  File "C:\Users\User\AppData\Local\Programs\Python\Python38-32\lib\site-packages\django\utils\functional.py", line 48, in __get__
    res = instance.__dict__[self.name] = self.func(instance)
  File "C:\Users\User\AppData\Local\Programs\Python\Python38-32\lib\site-packages\django\core\paginator.py", line 94, in count
    return c()
  File "C:\Users\User\AppData\Local\Programs\Python\Python38-32\lib\site-packages\django\db\models\query.py", line 411, in count
    return self.query.get_count(using=self.db)
  File "C:\Users\User\AppData\Local\Programs\Python\Python38-32\lib\site-packages\django\db\models\sql\query.py", line 515, in get_count
    number = obj.get_aggregation(using, ['__count'])['__count']
  File "C:\Users\User\AppData\Local\Programs\Python\Python38-32\lib\site-packages\django\db\models\sql\query.py", line 500, in get_aggregation
    result = compiler.execute_sql(SINGLE)
  File "C:\Users\User\AppData\Local\Programs\Python\Python38-32\lib\site-packages\django\db\models\sql\compiler.py", line 1156, in execute_sql
    cursor.execute(sql, params)
  File "C:\Users\User\AppData\Local\Programs\Python\Python38-32\lib\site-packages\django\db\backends\utils.py", line 98, in execute
    return super().execute(sql, params)
  File "C:\Users\User\AppData\Local\Programs\Python\Python38-32\lib\site-packages\django\db\backends\utils.py", line 66, in execute
    return self._execute_with_wrappers(sql, params, many=False, executor=self._execute)
  File "C:\Users\User\AppData\Local\Programs\Python\Python38-32\lib\site-packages\django\db\backends\utils.py", line 75, in _execute_with_wrappers
    return executor(sql, params, many, context)
  File "C:\Users\User\AppData\Local\Programs\Python\Python38-32\lib\site-packages\django\db\backends\utils.py", line 84, in _execute
    return self.cursor.execute(sql, params)
  File "C:\Users\User\AppData\Local\Programs\Python\Python38-32\lib\site-packages\django\db\utils.py", line 90, in __exit__
    raise dj_exc_value.with_traceback(traceback) from exc_value
  File "C:\Users\User\AppData\Local\Programs\Python\Python38-32\lib\site-packages\django\db\backends\utils.py", line 84, in _execute
    return self.cursor.execute(sql, params)
django.db.utils.ProgrammingError: relation "api_transaction" does not exist
LINE 1: SELECT COUNT(*) AS "__count" FROM "api_transaction"
                                          ^

2021-02-08 16:57:38,188 Internal Server Error: /admin/api/transaction/
Traceback (most recent call last):
  File "C:\Users\User\AppData\Local\Programs\Python\Python38-32\lib\site-packages\django\db\backends\utils.py", line 84, in _execute
    return self.cursor.execute(sql, params)
psycopg2.errors.UndefinedTable: relation "api_transaction" does not exist
LINE 1: SELECT COUNT(*) AS "__count" FROM "api_transaction"
                                          ^


The above exception was the direct cause of the following exception:

Traceback (most recent call last):
  File "C:\Users\User\AppData\Local\Programs\Python\Python38-32\lib\site-packages\django\core\handlers\exception.py", line 47, in inner
    response = get_response(request)
  File "C:\Users\User\AppData\Local\Programs\Python\Python38-32\lib\site-packages\django\core\handlers\base.py", line 179, in _get_response
    response = wrapped_callback(request, *callback_args, **callback_kwargs)
  File "C:\Users\User\AppData\Local\Programs\Python\Python38-32\lib\site-packages\django\contrib\admin\options.py", line 614, in wrapper
    return self.admin_site.admin_view(view)(*args, **kwargs)
  File "C:\Users\User\AppData\Local\Programs\Python\Python38-32\lib\site-packages\django\utils\decorators.py", line 130, in _wrapped_view
    response = view_func(request, *args, **kwargs)
  File "C:\Users\User\AppData\Local\Programs\Python\Python38-32\lib\site-packages\django\views\decorators\cache.py", line 44, in _wrapped_view_func
    response = view_func(request, *args, **kwargs)
  File "C:\Users\User\AppData\Local\Programs\Python\Python38-32\lib\site-packages\django\contrib\admin\sites.py", line 233, in inner
    return view(request, *args, **kwargs)
  File "C:\Users\User\AppData\Local\Programs\Python\Python38-32\lib\site-packages\django\utils\decorators.py", line 43, in _wrapper
    return bound_method(*args, **kwargs)
  File "C:\Users\User\AppData\Local\Programs\Python\Python38-32\lib\site-packages\django\utils\decorators.py", line 130, in _wrapped_view
    response = view_func(request, *args, **kwargs)
  File "C:\Users\User\AppData\Local\Programs\Python\Python38-32\lib\site-packages\django\contrib\admin\options.py", line 1693, in changelist_view
    cl = self.get_changelist_instance(request)
  File "C:\Users\User\AppData\Local\Programs\Python\Python38-32\lib\site-packages\django\contrib\admin\options.py", line 735, in get_changelist_instance
    return ChangeList(
  File "C:\Users\User\AppData\Local\Programs\Python\Python38-32\lib\site-packages\django\contrib\admin\views\main.py", line 100, in __init__
    self.get_results(request)
  File "C:\Users\User\AppData\Local\Programs\Python\Python38-32\lib\site-packages\django\contrib\admin\views\main.py", line 235, in get_results
    result_count = paginator.count
  File "C:\Users\User\AppData\Local\Programs\Python\Python38-32\lib\site-packages\django\utils\functional.py", line 48, in __get__
    res = instance.__dict__[self.name] = self.func(instance)
  File "C:\Users\User\AppData\Local\Programs\Python\Python38-32\lib\site-packages\django\core\paginator.py", line 94, in count
    return c()
  File "C:\Users\User\AppData\Local\Programs\Python\Python38-32\lib\site-packages\django\db\models\query.py", line 411, in count
    return self.query.get_count(using=self.db)
  File "C:\Users\User\AppData\Local\Programs\Python\Python38-32\lib\site-packages\django\db\models\sql\query.py", line 515, in get_count
    number = obj.get_aggregation(using, ['__count'])['__count']
  File "C:\Users\User\AppData\Local\Programs\Python\Python38-32\lib\site-packages\django\db\models\sql\query.py", line 500, in get_aggregation
    result = compiler.execute_sql(SINGLE)
  File "C:\Users\User\AppData\Local\Programs\Python\Python38-32\lib\site-packages\django\db\models\sql\compiler.py", line 1156, in execute_sql
    cursor.execute(sql, params)
  File "C:\Users\User\AppData\Local\Programs\Python\Python38-32\lib\site-packages\django\db\backends\utils.py", line 98, in execute
    return super().execute(sql, params)
  File "C:\Users\User\AppData\Local\Programs\Python\Python38-32\lib\site-packages\django\db\backends\utils.py", line 66, in execute
    return self._execute_with_wrappers(sql, params, many=False, executor=self._execute)
  File "C:\Users\User\AppData\Local\Programs\Python\Python38-32\lib\site-packages\django\db\backends\utils.py", line 75, in _execute_with_wrappers
    return executor(sql, params, many, context)
  File "C:\Users\User\AppData\Local\Programs\Python\Python38-32\lib\site-packages\django\db\backends\utils.py", line 84, in _execute
    return self.cursor.execute(sql, params)
  File "C:\Users\User\AppData\Local\Programs\Python\Python38-32\lib\site-packages\django\db\utils.py", line 90, in __exit__
    raise dj_exc_value.with_traceback(traceback) from exc_value
  File "C:\Users\User\AppData\Local\Programs\Python\Python38-32\lib\site-packages\django\db\backends\utils.py", line 84, in _execute
    return self.cursor.execute(sql, params)
django.db.utils.ProgrammingError: relation "api_transaction" does not exist
LINE 1: SELECT COUNT(*) AS "__count" FROM "api_transaction"
                                          ^

2021-02-08 17:01:41,261 Internal Server Error: /admin/api/transaction/add/
Traceback (most recent call last):
  File "C:\Users\User\AppData\Local\Programs\Python\Python38-32\lib\site-packages\django\db\backends\utils.py", line 84, in _execute
    return self.cursor.execute(sql, params)
psycopg2.errors.UndefinedTable: relation "api_transaction" does not exist
LINE 1: SELECT (1) AS "a" FROM "api_transaction" WHERE "api_transact...
                               ^


The above exception was the direct cause of the following exception:

Traceback (most recent call last):
  File "C:\Users\User\AppData\Local\Programs\Python\Python38-32\lib\site-packages\django\core\handlers\exception.py", line 47, in inner
    response = get_response(request)
  File "C:\Users\User\AppData\Local\Programs\Python\Python38-32\lib\site-packages\django\core\handlers\base.py", line 179, in _get_response
    response = wrapped_callback(request, *callback_args, **callback_kwargs)
  File "C:\Users\User\AppData\Local\Programs\Python\Python38-32\lib\site-packages\django\contrib\admin\options.py", line 614, in wrapper
    return self.admin_site.admin_view(view)(*args, **kwargs)
  File "C:\Users\User\AppData\Local\Programs\Python\Python38-32\lib\site-packages\django\utils\decorators.py", line 130, in _wrapped_view
    response = view_func(request, *args, **kwargs)
  File "C:\Users\User\AppData\Local\Programs\Python\Python38-32\lib\site-packages\django\views\decorators\cache.py", line 44, in _wrapped_view_func
    response = view_func(request, *args, **kwargs)
  File "C:\Users\User\AppData\Local\Programs\Python\Python38-32\lib\site-packages\django\contrib\admin\sites.py", line 233, in inner
    return view(request, *args, **kwargs)
  File "C:\Users\User\AppData\Local\Programs\Python\Python38-32\lib\site-packages\django\contrib\admin\options.py", line 1653, in add_view
    return self.changeform_view(request, None, form_url, extra_context)
  File "C:\Users\User\AppData\Local\Programs\Python\Python38-32\lib\site-packages\django\utils\decorators.py", line 43, in _wrapper
    return bound_method(*args, **kwargs)
  File "C:\Users\User\AppData\Local\Programs\Python\Python38-32\lib\site-packages\django\utils\decorators.py", line 130, in _wrapped_view
    response = view_func(request, *args, **kwargs)
  File "C:\Users\User\AppData\Local\Programs\Python\Python38-32\lib\site-packages\django\contrib\admin\options.py", line 1534, in changeform_view
    return self._changeform_view(request, object_id, form_url, extra_context)
  File "C:\Users\User\AppData\Local\Programs\Python\Python38-32\lib\site-packages\django\contrib\admin\options.py", line 1573, in _changeform_view
    form_validated = form.is_valid()
  File "C:\Users\User\AppData\Local\Programs\Python\Python38-32\lib\site-packages\django\forms\forms.py", line 177, in is_valid
    return self.is_bound and not self.errors
  File "C:\Users\User\AppData\Local\Programs\Python\Python38-32\lib\site-packages\django\forms\forms.py", line 172, in errors
    self.full_clean()
  File "C:\Users\User\AppData\Local\Programs\Python\Python38-32\lib\site-packages\django\forms\forms.py", line 376, in full_clean
    self._post_clean()
  File "C:\Users\User\AppData\Local\Programs\Python\Python38-32\lib\site-packages\django\forms\models.py", line 411, in _post_clean
    self.validate_unique()
  File "C:\Users\User\AppData\Local\Programs\Python\Python38-32\lib\site-packages\django\forms\models.py", line 420, in validate_unique
    self.instance.validate_unique(exclude=exclude)
  File "C:\Users\User\AppData\Local\Programs\Python\Python38-32\lib\site-packages\django\db\models\base.py", line 1009, in validate_unique
    errors = self._perform_unique_checks(unique_checks)
  File "C:\Users\User\AppData\Local\Programs\Python\Python38-32\lib\site-packages\django\db\models\base.py", line 1112, in _perform_unique_checks
    if qs.exists():
  File "C:\Users\User\AppData\Local\Programs\Python\Python38-32\lib\site-packages\django\db\models\query.py", line 809, in exists
    return self.query.has_results(using=self.db)
  File "C:\Users\User\AppData\Local\Programs\Python\Python38-32\lib\site-packages\django\db\models\sql\query.py", line 535, in has_results
    return compiler.has_results()
  File "C:\Users\User\AppData\Local\Programs\Python\Python38-32\lib\site-packages\django\db\models\sql\compiler.py", line 1126, in has_results
    return bool(self.execute_sql(SINGLE))
  File "C:\Users\User\AppData\Local\Programs\Python\Python38-32\lib\site-packages\django\db\models\sql\compiler.py", line 1156, in execute_sql
    cursor.execute(sql, params)
  File "C:\Users\User\AppData\Local\Programs\Python\Python38-32\lib\site-packages\django\db\backends\utils.py", line 98, in execute
    return super().execute(sql, params)
  File "C:\Users\User\AppData\Local\Programs\Python\Python38-32\lib\site-packages\django\db\backends\utils.py", line 66, in execute
    return self._execute_with_wrappers(sql, params, many=False, executor=self._execute)
  File "C:\Users\User\AppData\Local\Programs\Python\Python38-32\lib\site-packages\django\db\backends\utils.py", line 75, in _execute_with_wrappers
    return executor(sql, params, many, context)
  File "C:\Users\User\AppData\Local\Programs\Python\Python38-32\lib\site-packages\django\db\backends\utils.py", line 84, in _execute
    return self.cursor.execute(sql, params)
  File "C:\Users\User\AppData\Local\Programs\Python\Python38-32\lib\site-packages\django\db\utils.py", line 90, in __exit__
    raise dj_exc_value.with_traceback(traceback) from exc_value
  File "C:\Users\User\AppData\Local\Programs\Python\Python38-32\lib\site-packages\django\db\backends\utils.py", line 84, in _execute
    return self.cursor.execute(sql, params)
django.db.utils.ProgrammingError: relation "api_transaction" does not exist
LINE 1: SELECT (1) AS "a" FROM "api_transaction" WHERE "api_transact...
                               ^

2021-02-08 17:27:41,684 C:\ES_POST_API\es_post_api\api\views.py changed, reloading.
2021-02-08 17:31:35,286 Internal Server Error: /admin/api/transaction/
Traceback (most recent call last):
  File "C:\Users\User\AppData\Local\Programs\Python\Python38-32\lib\site-packages\django\db\backends\utils.py", line 84, in _execute
    return self.cursor.execute(sql, params)
psycopg2.errors.UndefinedTable: relation "api_transaction" does not exist
LINE 1: SELECT COUNT(*) AS "__count" FROM "api_transaction"
                                          ^


The above exception was the direct cause of the following exception:

Traceback (most recent call last):
  File "C:\Users\User\AppData\Local\Programs\Python\Python38-32\lib\site-packages\django\core\handlers\exception.py", line 47, in inner
    response = get_response(request)
  File "C:\Users\User\AppData\Local\Programs\Python\Python38-32\lib\site-packages\django\core\handlers\base.py", line 179, in _get_response
    response = wrapped_callback(request, *callback_args, **callback_kwargs)
  File "C:\Users\User\AppData\Local\Programs\Python\Python38-32\lib\site-packages\django\contrib\admin\options.py", line 614, in wrapper
    return self.admin_site.admin_view(view)(*args, **kwargs)
  File "C:\Users\User\AppData\Local\Programs\Python\Python38-32\lib\site-packages\django\utils\decorators.py", line 130, in _wrapped_view
    response = view_func(request, *args, **kwargs)
  File "C:\Users\User\AppData\Local\Programs\Python\Python38-32\lib\site-packages\django\views\decorators\cache.py", line 44, in _wrapped_view_func
    response = view_func(request, *args, **kwargs)
  File "C:\Users\User\AppData\Local\Programs\Python\Python38-32\lib\site-packages\django\contrib\admin\sites.py", line 233, in inner
    return view(request, *args, **kwargs)
  File "C:\Users\User\AppData\Local\Programs\Python\Python38-32\lib\site-packages\django\utils\decorators.py", line 43, in _wrapper
    return bound_method(*args, **kwargs)
  File "C:\Users\User\AppData\Local\Programs\Python\Python38-32\lib\site-packages\django\utils\decorators.py", line 130, in _wrapped_view
    response = view_func(request, *args, **kwargs)
  File "C:\Users\User\AppData\Local\Programs\Python\Python38-32\lib\site-packages\django\contrib\admin\options.py", line 1693, in changelist_view
    cl = self.get_changelist_instance(request)
  File "C:\Users\User\AppData\Local\Programs\Python\Python38-32\lib\site-packages\django\contrib\admin\options.py", line 735, in get_changelist_instance
    return ChangeList(
  File "C:\Users\User\AppData\Local\Programs\Python\Python38-32\lib\site-packages\django\contrib\admin\views\main.py", line 100, in __init__
    self.get_results(request)
  File "C:\Users\User\AppData\Local\Programs\Python\Python38-32\lib\site-packages\django\contrib\admin\views\main.py", line 235, in get_results
    result_count = paginator.count
  File "C:\Users\User\AppData\Local\Programs\Python\Python38-32\lib\site-packages\django\utils\functional.py", line 48, in __get__
    res = instance.__dict__[self.name] = self.func(instance)
  File "C:\Users\User\AppData\Local\Programs\Python\Python38-32\lib\site-packages\django\core\paginator.py", line 94, in count
    return c()
  File "C:\Users\User\AppData\Local\Programs\Python\Python38-32\lib\site-packages\django\db\models\query.py", line 411, in count
    return self.query.get_count(using=self.db)
  File "C:\Users\User\AppData\Local\Programs\Python\Python38-32\lib\site-packages\django\db\models\sql\query.py", line 515, in get_count
    number = obj.get_aggregation(using, ['__count'])['__count']
  File "C:\Users\User\AppData\Local\Programs\Python\Python38-32\lib\site-packages\django\db\models\sql\query.py", line 500, in get_aggregation
    result = compiler.execute_sql(SINGLE)
  File "C:\Users\User\AppData\Local\Programs\Python\Python38-32\lib\site-packages\django\db\models\sql\compiler.py", line 1156, in execute_sql
    cursor.execute(sql, params)
  File "C:\Users\User\AppData\Local\Programs\Python\Python38-32\lib\site-packages\django\db\backends\utils.py", line 98, in execute
    return super().execute(sql, params)
  File "C:\Users\User\AppData\Local\Programs\Python\Python38-32\lib\site-packages\django\db\backends\utils.py", line 66, in execute
    return self._execute_with_wrappers(sql, params, many=False, executor=self._execute)
  File "C:\Users\User\AppData\Local\Programs\Python\Python38-32\lib\site-packages\django\db\backends\utils.py", line 75, in _execute_with_wrappers
    return executor(sql, params, many, context)
  File "C:\Users\User\AppData\Local\Programs\Python\Python38-32\lib\site-packages\django\db\backends\utils.py", line 84, in _execute
    return self.cursor.execute(sql, params)
  File "C:\Users\User\AppData\Local\Programs\Python\Python38-32\lib\site-packages\django\db\utils.py", line 90, in __exit__
    raise dj_exc_value.with_traceback(traceback) from exc_value
  File "C:\Users\User\AppData\Local\Programs\Python\Python38-32\lib\site-packages\django\db\backends\utils.py", line 84, in _execute
    return self.cursor.execute(sql, params)
django.db.utils.ProgrammingError: relation "api_transaction" does not exist
LINE 1: SELECT COUNT(*) AS "__count" FROM "api_transaction"
                                          ^

2021-02-08 17:36:01,217 Internal Server Error: /admin/api/transaction/
Traceback (most recent call last):
  File "C:\Users\User\AppData\Local\Programs\Python\Python38-32\lib\site-packages\django\db\backends\utils.py", line 84, in _execute
    return self.cursor.execute(sql, params)
psycopg2.errors.UndefinedTable: relation "api_transaction" does not exist
LINE 1: SELECT COUNT(*) AS "__count" FROM "api_transaction"
                                          ^


The above exception was the direct cause of the following exception:

Traceback (most recent call last):
  File "C:\Users\User\AppData\Local\Programs\Python\Python38-32\lib\site-packages\django\core\handlers\exception.py", line 47, in inner
    response = get_response(request)
  File "C:\Users\User\AppData\Local\Programs\Python\Python38-32\lib\site-packages\django\core\handlers\base.py", line 179, in _get_response
    response = wrapped_callback(request, *callback_args, **callback_kwargs)
  File "C:\Users\User\AppData\Local\Programs\Python\Python38-32\lib\site-packages\django\contrib\admin\options.py", line 614, in wrapper
    return self.admin_site.admin_view(view)(*args, **kwargs)
  File "C:\Users\User\AppData\Local\Programs\Python\Python38-32\lib\site-packages\django\utils\decorators.py", line 130, in _wrapped_view
    response = view_func(request, *args, **kwargs)
  File "C:\Users\User\AppData\Local\Programs\Python\Python38-32\lib\site-packages\django\views\decorators\cache.py", line 44, in _wrapped_view_func
    response = view_func(request, *args, **kwargs)
  File "C:\Users\User\AppData\Local\Programs\Python\Python38-32\lib\site-packages\django\contrib\admin\sites.py", line 233, in inner
    return view(request, *args, **kwargs)
  File "C:\Users\User\AppData\Local\Programs\Python\Python38-32\lib\site-packages\django\utils\decorators.py", line 43, in _wrapper
    return bound_method(*args, **kwargs)
  File "C:\Users\User\AppData\Local\Programs\Python\Python38-32\lib\site-packages\django\utils\decorators.py", line 130, in _wrapped_view
    response = view_func(request, *args, **kwargs)
  File "C:\Users\User\AppData\Local\Programs\Python\Python38-32\lib\site-packages\django\contrib\admin\options.py", line 1693, in changelist_view
    cl = self.get_changelist_instance(request)
  File "C:\Users\User\AppData\Local\Programs\Python\Python38-32\lib\site-packages\django\contrib\admin\options.py", line 735, in get_changelist_instance
    return ChangeList(
  File "C:\Users\User\AppData\Local\Programs\Python\Python38-32\lib\site-packages\django\contrib\admin\views\main.py", line 100, in __init__
    self.get_results(request)
  File "C:\Users\User\AppData\Local\Programs\Python\Python38-32\lib\site-packages\django\contrib\admin\views\main.py", line 235, in get_results
    result_count = paginator.count
  File "C:\Users\User\AppData\Local\Programs\Python\Python38-32\lib\site-packages\django\utils\functional.py", line 48, in __get__
    res = instance.__dict__[self.name] = self.func(instance)
  File "C:\Users\User\AppData\Local\Programs\Python\Python38-32\lib\site-packages\django\core\paginator.py", line 94, in count
    return c()
  File "C:\Users\User\AppData\Local\Programs\Python\Python38-32\lib\site-packages\django\db\models\query.py", line 411, in count
    return self.query.get_count(using=self.db)
  File "C:\Users\User\AppData\Local\Programs\Python\Python38-32\lib\site-packages\django\db\models\sql\query.py", line 515, in get_count
    number = obj.get_aggregation(using, ['__count'])['__count']
  File "C:\Users\User\AppData\Local\Programs\Python\Python38-32\lib\site-packages\django\db\models\sql\query.py", line 500, in get_aggregation
    result = compiler.execute_sql(SINGLE)
  File "C:\Users\User\AppData\Local\Programs\Python\Python38-32\lib\site-packages\django\db\models\sql\compiler.py", line 1156, in execute_sql
    cursor.execute(sql, params)
  File "C:\Users\User\AppData\Local\Programs\Python\Python38-32\lib\site-packages\django\db\backends\utils.py", line 98, in execute
    return super().execute(sql, params)
  File "C:\Users\User\AppData\Local\Programs\Python\Python38-32\lib\site-packages\django\db\backends\utils.py", line 66, in execute
    return self._execute_with_wrappers(sql, params, many=False, executor=self._execute)
  File "C:\Users\User\AppData\Local\Programs\Python\Python38-32\lib\site-packages\django\db\backends\utils.py", line 75, in _execute_with_wrappers
    return executor(sql, params, many, context)
  File "C:\Users\User\AppData\Local\Programs\Python\Python38-32\lib\site-packages\django\db\backends\utils.py", line 84, in _execute
    return self.cursor.execute(sql, params)
  File "C:\Users\User\AppData\Local\Programs\Python\Python38-32\lib\site-packages\django\db\utils.py", line 90, in __exit__
    raise dj_exc_value.with_traceback(traceback) from exc_value
  File "C:\Users\User\AppData\Local\Programs\Python\Python38-32\lib\site-packages\django\db\backends\utils.py", line 84, in _execute
    return self.cursor.execute(sql, params)
django.db.utils.ProgrammingError: relation "api_transaction" does not exist
LINE 1: SELECT COUNT(*) AS "__count" FROM "api_transaction"
                                          ^

2021-02-08 17:47:32,499 Internal Server Error: /admin/api/transaction/
Traceback (most recent call last):
  File "C:\Users\User\AppData\Local\Programs\Python\Python38-32\lib\site-packages\django\db\backends\utils.py", line 84, in _execute
    return self.cursor.execute(sql, params)
psycopg2.errors.UndefinedTable: relation "api_transaction" does not exist
LINE 1: SELECT COUNT(*) AS "__count" FROM "api_transaction"
                                          ^


The above exception was the direct cause of the following exception:

Traceback (most recent call last):
  File "C:\Users\User\AppData\Local\Programs\Python\Python38-32\lib\site-packages\django\core\handlers\exception.py", line 47, in inner
    response = get_response(request)
  File "C:\Users\User\AppData\Local\Programs\Python\Python38-32\lib\site-packages\django\core\handlers\base.py", line 179, in _get_response
    response = wrapped_callback(request, *callback_args, **callback_kwargs)
  File "C:\Users\User\AppData\Local\Programs\Python\Python38-32\lib\site-packages\django\contrib\admin\options.py", line 614, in wrapper
    return self.admin_site.admin_view(view)(*args, **kwargs)
  File "C:\Users\User\AppData\Local\Programs\Python\Python38-32\lib\site-packages\django\utils\decorators.py", line 130, in _wrapped_view
    response = view_func(request, *args, **kwargs)
  File "C:\Users\User\AppData\Local\Programs\Python\Python38-32\lib\site-packages\django\views\decorators\cache.py", line 44, in _wrapped_view_func
    response = view_func(request, *args, **kwargs)
  File "C:\Users\User\AppData\Local\Programs\Python\Python38-32\lib\site-packages\django\contrib\admin\sites.py", line 233, in inner
    return view(request, *args, **kwargs)
  File "C:\Users\User\AppData\Local\Programs\Python\Python38-32\lib\site-packages\django\utils\decorators.py", line 43, in _wrapper
    return bound_method(*args, **kwargs)
  File "C:\Users\User\AppData\Local\Programs\Python\Python38-32\lib\site-packages\django\utils\decorators.py", line 130, in _wrapped_view
    response = view_func(request, *args, **kwargs)
  File "C:\Users\User\AppData\Local\Programs\Python\Python38-32\lib\site-packages\django\contrib\admin\options.py", line 1693, in changelist_view
    cl = self.get_changelist_instance(request)
  File "C:\Users\User\AppData\Local\Programs\Python\Python38-32\lib\site-packages\django\contrib\admin\options.py", line 735, in get_changelist_instance
    return ChangeList(
  File "C:\Users\User\AppData\Local\Programs\Python\Python38-32\lib\site-packages\django\contrib\admin\views\main.py", line 100, in __init__
    self.get_results(request)
  File "C:\Users\User\AppData\Local\Programs\Python\Python38-32\lib\site-packages\django\contrib\admin\views\main.py", line 235, in get_results
    result_count = paginator.count
  File "C:\Users\User\AppData\Local\Programs\Python\Python38-32\lib\site-packages\django\utils\functional.py", line 48, in __get__
    res = instance.__dict__[self.name] = self.func(instance)
  File "C:\Users\User\AppData\Local\Programs\Python\Python38-32\lib\site-packages\django\core\paginator.py", line 94, in count
    return c()
  File "C:\Users\User\AppData\Local\Programs\Python\Python38-32\lib\site-packages\django\db\models\query.py", line 411, in count
    return self.query.get_count(using=self.db)
  File "C:\Users\User\AppData\Local\Programs\Python\Python38-32\lib\site-packages\django\db\models\sql\query.py", line 515, in get_count
    number = obj.get_aggregation(using, ['__count'])['__count']
  File "C:\Users\User\AppData\Local\Programs\Python\Python38-32\lib\site-packages\django\db\models\sql\query.py", line 500, in get_aggregation
    result = compiler.execute_sql(SINGLE)
  File "C:\Users\User\AppData\Local\Programs\Python\Python38-32\lib\site-packages\django\db\models\sql\compiler.py", line 1156, in execute_sql
    cursor.execute(sql, params)
  File "C:\Users\User\AppData\Local\Programs\Python\Python38-32\lib\site-packages\django\db\backends\utils.py", line 98, in execute
    return super().execute(sql, params)
  File "C:\Users\User\AppData\Local\Programs\Python\Python38-32\lib\site-packages\django\db\backends\utils.py", line 66, in execute
    return self._execute_with_wrappers(sql, params, many=False, executor=self._execute)
  File "C:\Users\User\AppData\Local\Programs\Python\Python38-32\lib\site-packages\django\db\backends\utils.py", line 75, in _execute_with_wrappers
    return executor(sql, params, many, context)
  File "C:\Users\User\AppData\Local\Programs\Python\Python38-32\lib\site-packages\django\db\backends\utils.py", line 84, in _execute
    return self.cursor.execute(sql, params)
  File "C:\Users\User\AppData\Local\Programs\Python\Python38-32\lib\site-packages\django\db\utils.py", line 90, in __exit__
    raise dj_exc_value.with_traceback(traceback) from exc_value
  File "C:\Users\User\AppData\Local\Programs\Python\Python38-32\lib\site-packages\django\db\backends\utils.py", line 84, in _execute
    return self.cursor.execute(sql, params)
django.db.utils.ProgrammingError: relation "api_transaction" does not exist
LINE 1: SELECT COUNT(*) AS "__count" FROM "api_transaction"
                                          ^

2021-02-08 19:20:39,282 Not Found: /
2021-02-08 19:20:39,717 Not Found: /favicon.ico
2021-02-08 19:20:50,506 Internal Server Error: /admin/api/transaction/
Traceback (most recent call last):
  File "C:\Users\User\AppData\Local\Programs\Python\Python38-32\lib\site-packages\django\db\backends\utils.py", line 84, in _execute
    return self.cursor.execute(sql, params)
psycopg2.errors.UndefinedTable: relation "api_transaction" does not exist
LINE 1: SELECT COUNT(*) AS "__count" FROM "api_transaction"
                                          ^


The above exception was the direct cause of the following exception:

Traceback (most recent call last):
  File "C:\Users\User\AppData\Local\Programs\Python\Python38-32\lib\site-packages\django\core\handlers\exception.py", line 47, in inner
    response = get_response(request)
  File "C:\Users\User\AppData\Local\Programs\Python\Python38-32\lib\site-packages\django\core\handlers\base.py", line 179, in _get_response
    response = wrapped_callback(request, *callback_args, **callback_kwargs)
  File "C:\Users\User\AppData\Local\Programs\Python\Python38-32\lib\site-packages\django\contrib\admin\options.py", line 614, in wrapper
    return self.admin_site.admin_view(view)(*args, **kwargs)
  File "C:\Users\User\AppData\Local\Programs\Python\Python38-32\lib\site-packages\django\utils\decorators.py", line 130, in _wrapped_view
    response = view_func(request, *args, **kwargs)
  File "C:\Users\User\AppData\Local\Programs\Python\Python38-32\lib\site-packages\django\views\decorators\cache.py", line 44, in _wrapped_view_func
    response = view_func(request, *args, **kwargs)
  File "C:\Users\User\AppData\Local\Programs\Python\Python38-32\lib\site-packages\django\contrib\admin\sites.py", line 233, in inner
    return view(request, *args, **kwargs)
  File "C:\Users\User\AppData\Local\Programs\Python\Python38-32\lib\site-packages\django\utils\decorators.py", line 43, in _wrapper
    return bound_method(*args, **kwargs)
  File "C:\Users\User\AppData\Local\Programs\Python\Python38-32\lib\site-packages\django\utils\decorators.py", line 130, in _wrapped_view
    response = view_func(request, *args, **kwargs)
  File "C:\Users\User\AppData\Local\Programs\Python\Python38-32\lib\site-packages\django\contrib\admin\options.py", line 1693, in changelist_view
    cl = self.get_changelist_instance(request)
  File "C:\Users\User\AppData\Local\Programs\Python\Python38-32\lib\site-packages\django\contrib\admin\options.py", line 735, in get_changelist_instance
    return ChangeList(
  File "C:\Users\User\AppData\Local\Programs\Python\Python38-32\lib\site-packages\django\contrib\admin\views\main.py", line 100, in __init__
    self.get_results(request)
  File "C:\Users\User\AppData\Local\Programs\Python\Python38-32\lib\site-packages\django\contrib\admin\views\main.py", line 235, in get_results
    result_count = paginator.count
  File "C:\Users\User\AppData\Local\Programs\Python\Python38-32\lib\site-packages\django\utils\functional.py", line 48, in __get__
    res = instance.__dict__[self.name] = self.func(instance)
  File "C:\Users\User\AppData\Local\Programs\Python\Python38-32\lib\site-packages\django\core\paginator.py", line 94, in count
    return c()
  File "C:\Users\User\AppData\Local\Programs\Python\Python38-32\lib\site-packages\django\db\models\query.py", line 411, in count
    return self.query.get_count(using=self.db)
  File "C:\Users\User\AppData\Local\Programs\Python\Python38-32\lib\site-packages\django\db\models\sql\query.py", line 515, in get_count
    number = obj.get_aggregation(using, ['__count'])['__count']
  File "C:\Users\User\AppData\Local\Programs\Python\Python38-32\lib\site-packages\django\db\models\sql\query.py", line 500, in get_aggregation
    result = compiler.execute_sql(SINGLE)
  File "C:\Users\User\AppData\Local\Programs\Python\Python38-32\lib\site-packages\django\db\models\sql\compiler.py", line 1156, in execute_sql
    cursor.execute(sql, params)
  File "C:\Users\User\AppData\Local\Programs\Python\Python38-32\lib\site-packages\django\db\backends\utils.py", line 98, in execute
    return super().execute(sql, params)
  File "C:\Users\User\AppData\Local\Programs\Python\Python38-32\lib\site-packages\django\db\backends\utils.py", line 66, in execute
    return self._execute_with_wrappers(sql, params, many=False, executor=self._execute)
  File "C:\Users\User\AppData\Local\Programs\Python\Python38-32\lib\site-packages\django\db\backends\utils.py", line 75, in _execute_with_wrappers
    return executor(sql, params, many, context)
  File "C:\Users\User\AppData\Local\Programs\Python\Python38-32\lib\site-packages\django\db\backends\utils.py", line 84, in _execute
    return self.cursor.execute(sql, params)
  File "C:\Users\User\AppData\Local\Programs\Python\Python38-32\lib\site-packages\django\db\utils.py", line 90, in __exit__
    raise dj_exc_value.with_traceback(traceback) from exc_value
  File "C:\Users\User\AppData\Local\Programs\Python\Python38-32\lib\site-packages\django\db\backends\utils.py", line 84, in _execute
    return self.cursor.execute(sql, params)
django.db.utils.ProgrammingError: relation "api_transaction" does not exist
LINE 1: SELECT COUNT(*) AS "__count" FROM "api_transaction"
                                          ^

2021-02-08 19:30:42,734 C:\ES_POST_API\es_post_api\es_post_api\settings.py changed, reloading.
2021-02-08 19:49:26,672 b'{"transaction_ts":["This field is required."]}'
2021-02-08 19:49:26,690 Bad Request: /transaction_details/send/
2021-02-08 19:49:48,400 b'{"non_field_errors":["transaction_type must be between 1-4"]}'
2021-02-08 19:49:48,401 Bad Request: /transaction_details/send/
2021-02-08 19:50:10,764 Data Created Successfully
2021-02-08 20:10:07,884 C:\ES_POST_API\es_post_api\api\serializers.py changed, reloading.
2021-02-08 20:10:59,901 b'{"transaction_id":["transaction with this transaction id already exists."]}'
2021-02-08 20:10:59,903 Bad Request: /transaction_details/send/
2021-02-08 20:11:28,168 Internal Server Error: /transaction_details/send/
Traceback (most recent call last):
  File "C:\Users\User\AppData\Local\Programs\Python\Python38-32\lib\site-packages\django\core\handlers\exception.py", line 47, in inner
    response = get_response(request)
  File "C:\Users\User\AppData\Local\Programs\Python\Python38-32\lib\site-packages\django\core\handlers\base.py", line 179, in _get_response
    response = wrapped_callback(request, *callback_args, **callback_kwargs)
  File "C:\Users\User\AppData\Local\Programs\Python\Python38-32\lib\site-packages\django\views\decorators\csrf.py", line 54, in wrapped_view
    return view_func(*args, **kwargs)
  File "C:\Users\User\AppData\Local\Programs\Python\Python38-32\lib\site-packages\django\views\decorators\csrf.py", line 54, in wrapped_view
    return view_func(*args, **kwargs)
  File "C:\Users\User\AppData\Local\Programs\Python\Python38-32\lib\site-packages\django\views\generic\base.py", line 70, in view
    return self.dispatch(request, *args, **kwargs)
  File "C:\Users\User\AppData\Local\Programs\Python\Python38-32\lib\site-packages\rest_framework\views.py", line 509, in dispatch
    response = self.handle_exception(exc)
  File "C:\Users\User\AppData\Local\Programs\Python\Python38-32\lib\site-packages\rest_framework\views.py", line 469, in handle_exception
    self.raise_uncaught_exception(exc)
  File "C:\Users\User\AppData\Local\Programs\Python\Python38-32\lib\site-packages\rest_framework\views.py", line 480, in raise_uncaught_exception
    raise exc
  File "C:\Users\User\AppData\Local\Programs\Python\Python38-32\lib\site-packages\rest_framework\views.py", line 506, in dispatch
    response = handler(request, *args, **kwargs)
  File "C:\Users\User\AppData\Local\Programs\Python\Python38-32\lib\site-packages\rest_framework\decorators.py", line 50, in handler
    return func(*args, **kwargs)
  File "C:\ES_POST_API\es_post_api\api\views.py", line 46, in addTransaction
    if serializer.is_valid():
  File "C:\Users\User\AppData\Local\Programs\Python\Python38-32\lib\site-packages\rest_framework\serializers.py", line 220, in is_valid
    self._validated_data = self.run_validation(self.initial_data)
  File "C:\Users\User\AppData\Local\Programs\Python\Python38-32\lib\site-packages\rest_framework\serializers.py", line 422, in run_validation
    value = self.validate(value)
  File "C:\ES_POST_API\es_post_api\api\serializers.py", line 28, in validate
    if datetime.now() > transaction_ts :
TypeError: can't compare offset-naive and offset-aware datetimes
2021-02-08 20:11:44,568 Internal Server Error: /transaction_details/send/
Traceback (most recent call last):
  File "C:\Users\User\AppData\Local\Programs\Python\Python38-32\lib\site-packages\django\core\handlers\exception.py", line 47, in inner
    response = get_response(request)
  File "C:\Users\User\AppData\Local\Programs\Python\Python38-32\lib\site-packages\django\core\handlers\base.py", line 179, in _get_response
    response = wrapped_callback(request, *callback_args, **callback_kwargs)
  File "C:\Users\User\AppData\Local\Programs\Python\Python38-32\lib\site-packages\django\views\decorators\csrf.py", line 54, in wrapped_view
    return view_func(*args, **kwargs)
  File "C:\Users\User\AppData\Local\Programs\Python\Python38-32\lib\site-packages\django\views\decorators\csrf.py", line 54, in wrapped_view
    return view_func(*args, **kwargs)
  File "C:\Users\User\AppData\Local\Programs\Python\Python38-32\lib\site-packages\django\views\generic\base.py", line 70, in view
    return self.dispatch(request, *args, **kwargs)
  File "C:\Users\User\AppData\Local\Programs\Python\Python38-32\lib\site-packages\rest_framework\views.py", line 509, in dispatch
    response = self.handle_exception(exc)
  File "C:\Users\User\AppData\Local\Programs\Python\Python38-32\lib\site-packages\rest_framework\views.py", line 469, in handle_exception
    self.raise_uncaught_exception(exc)
  File "C:\Users\User\AppData\Local\Programs\Python\Python38-32\lib\site-packages\rest_framework\views.py", line 480, in raise_uncaught_exception
    raise exc
  File "C:\Users\User\AppData\Local\Programs\Python\Python38-32\lib\site-packages\rest_framework\views.py", line 506, in dispatch
    response = handler(request, *args, **kwargs)
  File "C:\Users\User\AppData\Local\Programs\Python\Python38-32\lib\site-packages\rest_framework\decorators.py", line 50, in handler
    return func(*args, **kwargs)
  File "C:\ES_POST_API\es_post_api\api\views.py", line 46, in addTransaction
    if serializer.is_valid():
  File "C:\Users\User\AppData\Local\Programs\Python\Python38-32\lib\site-packages\rest_framework\serializers.py", line 220, in is_valid
    self._validated_data = self.run_validation(self.initial_data)
  File "C:\Users\User\AppData\Local\Programs\Python\Python38-32\lib\site-packages\rest_framework\serializers.py", line 422, in run_validation
    value = self.validate(value)
  File "C:\ES_POST_API\es_post_api\api\serializers.py", line 28, in validate
    if datetime.now() > transaction_ts :
TypeError: can't compare offset-naive and offset-aware datetimes
2021-02-08 20:12:06,698 Internal Server Error: /transaction_details/send/
Traceback (most recent call last):
  File "C:\Users\User\AppData\Local\Programs\Python\Python38-32\lib\site-packages\django\core\handlers\exception.py", line 47, in inner
    response = get_response(request)
  File "C:\Users\User\AppData\Local\Programs\Python\Python38-32\lib\site-packages\django\core\handlers\base.py", line 179, in _get_response
    response = wrapped_callback(request, *callback_args, **callback_kwargs)
  File "C:\Users\User\AppData\Local\Programs\Python\Python38-32\lib\site-packages\django\views\decorators\csrf.py", line 54, in wrapped_view
    return view_func(*args, **kwargs)
  File "C:\Users\User\AppData\Local\Programs\Python\Python38-32\lib\site-packages\django\views\decorators\csrf.py", line 54, in wrapped_view
    return view_func(*args, **kwargs)
  File "C:\Users\User\AppData\Local\Programs\Python\Python38-32\lib\site-packages\django\views\generic\base.py", line 70, in view
    return self.dispatch(request, *args, **kwargs)
  File "C:\Users\User\AppData\Local\Programs\Python\Python38-32\lib\site-packages\rest_framework\views.py", line 509, in dispatch
    response = self.handle_exception(exc)
  File "C:\Users\User\AppData\Local\Programs\Python\Python38-32\lib\site-packages\rest_framework\views.py", line 469, in handle_exception
    self.raise_uncaught_exception(exc)
  File "C:\Users\User\AppData\Local\Programs\Python\Python38-32\lib\site-packages\rest_framework\views.py", line 480, in raise_uncaught_exception
    raise exc
  File "C:\Users\User\AppData\Local\Programs\Python\Python38-32\lib\site-packages\rest_framework\views.py", line 506, in dispatch
    response = handler(request, *args, **kwargs)
  File "C:\Users\User\AppData\Local\Programs\Python\Python38-32\lib\site-packages\rest_framework\decorators.py", line 50, in handler
    return func(*args, **kwargs)
  File "C:\ES_POST_API\es_post_api\api\views.py", line 46, in addTransaction
    if serializer.is_valid():
  File "C:\Users\User\AppData\Local\Programs\Python\Python38-32\lib\site-packages\rest_framework\serializers.py", line 220, in is_valid
    self._validated_data = self.run_validation(self.initial_data)
  File "C:\Users\User\AppData\Local\Programs\Python\Python38-32\lib\site-packages\rest_framework\serializers.py", line 422, in run_validation
    value = self.validate(value)
  File "C:\ES_POST_API\es_post_api\api\serializers.py", line 28, in validate
    if datetime.now() > transaction_ts :
TypeError: can't compare offset-naive and offset-aware datetimes
2021-02-08 20:12:15,597 Internal Server Error: /transaction_details/send/
Traceback (most recent call last):
  File "C:\Users\User\AppData\Local\Programs\Python\Python38-32\lib\site-packages\django\core\handlers\exception.py", line 47, in inner
    response = get_response(request)
  File "C:\Users\User\AppData\Local\Programs\Python\Python38-32\lib\site-packages\django\core\handlers\base.py", line 179, in _get_response
    response = wrapped_callback(request, *callback_args, **callback_kwargs)
  File "C:\Users\User\AppData\Local\Programs\Python\Python38-32\lib\site-packages\django\views\decorators\csrf.py", line 54, in wrapped_view
    return view_func(*args, **kwargs)
  File "C:\Users\User\AppData\Local\Programs\Python\Python38-32\lib\site-packages\django\views\decorators\csrf.py", line 54, in wrapped_view
    return view_func(*args, **kwargs)
  File "C:\Users\User\AppData\Local\Programs\Python\Python38-32\lib\site-packages\django\views\generic\base.py", line 70, in view
    return self.dispatch(request, *args, **kwargs)
  File "C:\Users\User\AppData\Local\Programs\Python\Python38-32\lib\site-packages\rest_framework\views.py", line 509, in dispatch
    response = self.handle_exception(exc)
  File "C:\Users\User\AppData\Local\Programs\Python\Python38-32\lib\site-packages\rest_framework\views.py", line 469, in handle_exception
    self.raise_uncaught_exception(exc)
  File "C:\Users\User\AppData\Local\Programs\Python\Python38-32\lib\site-packages\rest_framework\views.py", line 480, in raise_uncaught_exception
    raise exc
  File "C:\Users\User\AppData\Local\Programs\Python\Python38-32\lib\site-packages\rest_framework\views.py", line 506, in dispatch
    response = handler(request, *args, **kwargs)
  File "C:\Users\User\AppData\Local\Programs\Python\Python38-32\lib\site-packages\rest_framework\decorators.py", line 50, in handler
    return func(*args, **kwargs)
  File "C:\ES_POST_API\es_post_api\api\views.py", line 46, in addTransaction
    if serializer.is_valid():
  File "C:\Users\User\AppData\Local\Programs\Python\Python38-32\lib\site-packages\rest_framework\serializers.py", line 220, in is_valid
    self._validated_data = self.run_validation(self.initial_data)
  File "C:\Users\User\AppData\Local\Programs\Python\Python38-32\lib\site-packages\rest_framework\serializers.py", line 422, in run_validation
    value = self.validate(value)
  File "C:\ES_POST_API\es_post_api\api\serializers.py", line 28, in validate
    if datetime.now() > transaction_ts :
TypeError: can't compare offset-naive and offset-aware datetimes
2021-02-08 20:12:30,544 C:\ES_POST_API\es_post_api\api\serializers.py changed, reloading.
2021-02-08 20:12:38,465 Data Created Successfully
2021-02-08 20:25:17,742 C:\ES_POST_API\es_post_api\api\serializers.py changed, reloading.
2021-02-08 20:26:00,730 Internal Server Error: /transaction_details/send/
Traceback (most recent call last):
  File "C:\Users\User\AppData\Local\Programs\Python\Python38-32\lib\site-packages\django\core\handlers\exception.py", line 47, in inner
    response = get_response(request)
  File "C:\Users\User\AppData\Local\Programs\Python\Python38-32\lib\site-packages\django\core\handlers\base.py", line 179, in _get_response
    response = wrapped_callback(request, *callback_args, **callback_kwargs)
  File "C:\Users\User\AppData\Local\Programs\Python\Python38-32\lib\site-packages\django\views\decorators\csrf.py", line 54, in wrapped_view
    return view_func(*args, **kwargs)
  File "C:\Users\User\AppData\Local\Programs\Python\Python38-32\lib\site-packages\django\views\decorators\csrf.py", line 54, in wrapped_view
    return view_func(*args, **kwargs)
  File "C:\Users\User\AppData\Local\Programs\Python\Python38-32\lib\site-packages\django\views\generic\base.py", line 70, in view
    return self.dispatch(request, *args, **kwargs)
  File "C:\Users\User\AppData\Local\Programs\Python\Python38-32\lib\site-packages\rest_framework\views.py", line 509, in dispatch
    response = self.handle_exception(exc)
  File "C:\Users\User\AppData\Local\Programs\Python\Python38-32\lib\site-packages\rest_framework\views.py", line 469, in handle_exception
    self.raise_uncaught_exception(exc)
  File "C:\Users\User\AppData\Local\Programs\Python\Python38-32\lib\site-packages\rest_framework\views.py", line 480, in raise_uncaught_exception
    raise exc
  File "C:\Users\User\AppData\Local\Programs\Python\Python38-32\lib\site-packages\rest_framework\views.py", line 506, in dispatch
    response = handler(request, *args, **kwargs)
  File "C:\Users\User\AppData\Local\Programs\Python\Python38-32\lib\site-packages\rest_framework\decorators.py", line 50, in handler
    return func(*args, **kwargs)
  File "C:\ES_POST_API\es_post_api\api\views.py", line 46, in addTransaction
    if serializer.is_valid():
  File "C:\Users\User\AppData\Local\Programs\Python\Python38-32\lib\site-packages\rest_framework\serializers.py", line 220, in is_valid
    self._validated_data = self.run_validation(self.initial_data)
  File "C:\Users\User\AppData\Local\Programs\Python\Python38-32\lib\site-packages\rest_framework\serializers.py", line 422, in run_validation
    value = self.validate(value)
  File "C:\ES_POST_API\es_post_api\api\serializers.py", line 24, in validate
    if expiry_date < date.today() :
UnboundLocalError: local variable 'date' referenced before assignment
2021-02-08 20:26:13,611 C:\ES_POST_API\es_post_api\api\serializers.py changed, reloading.
2021-02-08 20:26:23,247 C:\ES_POST_API\es_post_api\api\serializers.py changed, reloading.
2021-02-08 20:26:30,895 Internal Server Error: /transaction_details/send/
Traceback (most recent call last):
  File "C:\Users\User\AppData\Local\Programs\Python\Python38-32\lib\site-packages\django\core\handlers\exception.py", line 47, in inner
    response = get_response(request)
  File "C:\Users\User\AppData\Local\Programs\Python\Python38-32\lib\site-packages\django\core\handlers\base.py", line 179, in _get_response
    response = wrapped_callback(request, *callback_args, **callback_kwargs)
  File "C:\Users\User\AppData\Local\Programs\Python\Python38-32\lib\site-packages\django\views\decorators\csrf.py", line 54, in wrapped_view
    return view_func(*args, **kwargs)
  File "C:\Users\User\AppData\Local\Programs\Python\Python38-32\lib\site-packages\django\views\decorators\csrf.py", line 54, in wrapped_view
    return view_func(*args, **kwargs)
  File "C:\Users\User\AppData\Local\Programs\Python\Python38-32\lib\site-packages\django\views\generic\base.py", line 70, in view
    return self.dispatch(request, *args, **kwargs)
  File "C:\Users\User\AppData\Local\Programs\Python\Python38-32\lib\site-packages\rest_framework\views.py", line 509, in dispatch
    response = self.handle_exception(exc)
  File "C:\Users\User\AppData\Local\Programs\Python\Python38-32\lib\site-packages\rest_framework\views.py", line 469, in handle_exception
    self.raise_uncaught_exception(exc)
  File "C:\Users\User\AppData\Local\Programs\Python\Python38-32\lib\site-packages\rest_framework\views.py", line 480, in raise_uncaught_exception
    raise exc
  File "C:\Users\User\AppData\Local\Programs\Python\Python38-32\lib\site-packages\rest_framework\views.py", line 506, in dispatch
    response = handler(request, *args, **kwargs)
  File "C:\Users\User\AppData\Local\Programs\Python\Python38-32\lib\site-packages\rest_framework\decorators.py", line 50, in handler
    return func(*args, **kwargs)
  File "C:\ES_POST_API\es_post_api\api\views.py", line 46, in addTransaction
    if serializer.is_valid():
  File "C:\Users\User\AppData\Local\Programs\Python\Python38-32\lib\site-packages\rest_framework\serializers.py", line 220, in is_valid
    self._validated_data = self.run_validation(self.initial_data)
  File "C:\Users\User\AppData\Local\Programs\Python\Python38-32\lib\site-packages\rest_framework\serializers.py", line 422, in run_validation
    value = self.validate(value)
  File "C:\ES_POST_API\es_post_api\api\serializers.py", line 24, in validate
    if expiry_date < date.today() :
UnboundLocalError: local variable 'date' referenced before assignment
2021-02-08 20:52:40,041 C:\ES_POST_API\es_post_api\api\serializers.py changed, reloading.
2021-02-08 20:53:06,680 b'{"non_field_errors":["[ErrorDetail(string=\'transaction_type must be between 1-4\', code=\'invalid\')]"]}'
2021-02-08 20:53:06,681 Bad Request: /transaction_details/send/
2021-02-08 20:53:58,288 C:\ES_POST_API\es_post_api\api\serializers.py changed, reloading.
2021-02-08 20:54:15,986 Internal Server Error: /transaction_details/send/
Traceback (most recent call last):
  File "C:\Users\User\AppData\Local\Programs\Python\Python38-32\lib\site-packages\django\core\handlers\exception.py", line 47, in inner
    response = get_response(request)
  File "C:\Users\User\AppData\Local\Programs\Python\Python38-32\lib\site-packages\django\core\handlers\base.py", line 179, in _get_response
    response = wrapped_callback(request, *callback_args, **callback_kwargs)
  File "C:\Users\User\AppData\Local\Programs\Python\Python38-32\lib\site-packages\django\views\decorators\csrf.py", line 54, in wrapped_view
    return view_func(*args, **kwargs)
  File "C:\Users\User\AppData\Local\Programs\Python\Python38-32\lib\site-packages\django\views\decorators\csrf.py", line 54, in wrapped_view
    return view_func(*args, **kwargs)
  File "C:\Users\User\AppData\Local\Programs\Python\Python38-32\lib\site-packages\django\views\generic\base.py", line 70, in view
    return self.dispatch(request, *args, **kwargs)
  File "C:\Users\User\AppData\Local\Programs\Python\Python38-32\lib\site-packages\rest_framework\views.py", line 509, in dispatch
    response = self.handle_exception(exc)
  File "C:\Users\User\AppData\Local\Programs\Python\Python38-32\lib\site-packages\rest_framework\views.py", line 469, in handle_exception
    self.raise_uncaught_exception(exc)
  File "C:\Users\User\AppData\Local\Programs\Python\Python38-32\lib\site-packages\rest_framework\views.py", line 480, in raise_uncaught_exception
    raise exc
  File "C:\Users\User\AppData\Local\Programs\Python\Python38-32\lib\site-packages\rest_framework\views.py", line 506, in dispatch
    response = handler(request, *args, **kwargs)
  File "C:\Users\User\AppData\Local\Programs\Python\Python38-32\lib\site-packages\rest_framework\decorators.py", line 50, in handler
    return func(*args, **kwargs)
  File "C:\ES_POST_API\es_post_api\api\views.py", line 46, in addTransaction
    if serializer.is_valid():
  File "C:\Users\User\AppData\Local\Programs\Python\Python38-32\lib\site-packages\rest_framework\serializers.py", line 220, in is_valid
    self._validated_data = self.run_validation(self.initial_data)
  File "C:\Users\User\AppData\Local\Programs\Python\Python38-32\lib\site-packages\rest_framework\serializers.py", line 422, in run_validation
    value = self.validate(value)
  File "C:\ES_POST_API\es_post_api\api\serializers.py", line 37, in validate
    raise ValidationError(error)
NameError: name 'ValidationError' is not defined
2021-02-08 20:55:27,557 C:\ES_POST_API\es_post_api\api\serializers.py changed, reloading.
2021-02-08 20:55:34,507 Internal Server Error: /transaction_details/send/
Traceback (most recent call last):
  File "C:\Users\User\AppData\Local\Programs\Python\Python38-32\lib\site-packages\django\core\handlers\exception.py", line 47, in inner
    response = get_response(request)
  File "C:\Users\User\AppData\Local\Programs\Python\Python38-32\lib\site-packages\django\core\handlers\base.py", line 179, in _get_response
    response = wrapped_callback(request, *callback_args, **callback_kwargs)
  File "C:\Users\User\AppData\Local\Programs\Python\Python38-32\lib\site-packages\django\views\decorators\csrf.py", line 54, in wrapped_view
    return view_func(*args, **kwargs)
  File "C:\Users\User\AppData\Local\Programs\Python\Python38-32\lib\site-packages\django\views\decorators\csrf.py", line 54, in wrapped_view
    return view_func(*args, **kwargs)
  File "C:\Users\User\AppData\Local\Programs\Python\Python38-32\lib\site-packages\django\views\generic\base.py", line 70, in view
    return self.dispatch(request, *args, **kwargs)
  File "C:\Users\User\AppData\Local\Programs\Python\Python38-32\lib\site-packages\rest_framework\views.py", line 509, in dispatch
    response = self.handle_exception(exc)
  File "C:\Users\User\AppData\Local\Programs\Python\Python38-32\lib\site-packages\rest_framework\views.py", line 469, in handle_exception
    self.raise_uncaught_exception(exc)
  File "C:\Users\User\AppData\Local\Programs\Python\Python38-32\lib\site-packages\rest_framework\views.py", line 480, in raise_uncaught_exception
    raise exc
  File "C:\Users\User\AppData\Local\Programs\Python\Python38-32\lib\site-packages\rest_framework\views.py", line 506, in dispatch
    response = handler(request, *args, **kwargs)
  File "C:\Users\User\AppData\Local\Programs\Python\Python38-32\lib\site-packages\rest_framework\decorators.py", line 50, in handler
    return func(*args, **kwargs)
  File "C:\ES_POST_API\es_post_api\api\views.py", line 46, in addTransaction
    if serializer.is_valid():
  File "C:\Users\User\AppData\Local\Programs\Python\Python38-32\lib\site-packages\rest_framework\serializers.py", line 220, in is_valid
    self._validated_data = self.run_validation(self.initial_data)
  File "C:\Users\User\AppData\Local\Programs\Python\Python38-32\lib\site-packages\rest_framework\serializers.py", line 422, in run_validation
    value = self.validate(value)
  File "C:\ES_POST_API\es_post_api\api\serializers.py", line 37, in validate
    raise ValidationError(error)
NameError: name 'ValidationError' is not defined
2021-02-08 20:56:47,992 C:\ES_POST_API\es_post_api\api\serializers.py changed, reloading.
2021-02-08 20:57:06,234 C:\ES_POST_API\es_post_api\api\serializers.py changed, reloading.
2021-02-08 20:57:11,417 b'{"non_field_errors":["transaction_type must be between 1-4"]}'
2021-02-08 20:57:11,419 Bad Request: /transaction_details/send/
2021-02-08 20:57:31,351 b'{"transaction_id":["transaction with this transaction id already exists."]}'
2021-02-08 20:57:31,351 Bad Request: /transaction_details/send/
2021-02-08 21:16:23,261 C:\ES_POST_API\es_post_api\api\serializers.py changed, reloading.
2021-02-08 21:16:35,904 b'{"transaction_id":["transaction with this transaction id already exists."]}'
2021-02-08 21:16:35,904 Bad Request: /transaction_details/send/
2021-02-08 21:23:22,424 b'{"non_field_errors":["[ErrorDetail(string=\'transaction_type must be between 1-4\', code=\'invalid\')]","[ErrorDetail(string=\'Invalid expiry_date\', code=\'invalid\')]"]}'
2021-02-08 21:23:22,425 Bad Request: /transaction_details/send/
2021-02-08 21:25:47,415 C:\ES_POST_API\es_post_api\api\serializers.py changed, reloading.
2021-02-08 21:25:56,580 b'{"non_field_errors":["[ErrorDetail(string=\'transaction_type must be between 1-4\', code=400)]","[ErrorDetail(string=\'Invalid expiry_date\', code=400)]"]}'
2021-02-08 21:25:56,580 Bad Request: /transaction_details/send/
2021-02-09 09:26:32,817 Not Found: /favicon.ico
2021-02-09 09:36:06,723 Data Created Successfully
2021-02-09 09:40:06,905 C:\ES_POST_API\es_post_api\es_post_api\settings.py changed, reloading.
2021-02-09 09:42:03,880 Data Created Successfully
2021-02-09 14:35:52,322 b'{"non_field_errors":["[ErrorDetail(string=\'Not a valid mrp\', code=400)]","[ErrorDetail(string=\'Invalid expiry_date\', code=400)]"]}'
2021-02-09 14:35:52,347 Bad Request: /transaction_details/send/
2021-02-09 15:13:44,567 Data Created Successfully
2021-02-09 15:14:54,535 b'{"non_field_errors":["[ErrorDetail(string=\'transaction_type must be between 1-4\', code=400)]","[ErrorDetail(string=\'Invalid expiry_date\', code=400)]"]}'
2021-02-09 15:14:54,536 Bad Request: /transaction_details/send/
2021-02-09 15:19:55,727 Data Created Successfully
2021-02-09 15:20:53,990 b'{"transaction_id":["transaction with this transaction id already exists."]}'
2021-02-09 15:20:53,991 Bad Request: /transaction_details/send/
2021-02-09 15:21:07,255 b'{"non_field_errors":["[ErrorDetail(string=\'transaction_type must be between 1-4\', code=400)]","[ErrorDetail(string=\'Invalid expiry_date\', code=400)]"]}'
2021-02-09 15:21:07,256 Bad Request: /transaction_details/send/
