2021-11-02 11:42:59,595 b'[{"transaction_id":["transaction with this transaction id already exists."]}]'
2021-11-02 11:42:59,596 Bad Request: /transaction_details/send/
2021-11-02 11:50:07,554 Internal Server Error: /transaction_details/send/
Traceback (most recent call last):
  File "C:\Users\User\AppData\Local\Programs\Python\Python38-32\lib\site-packages\rest_framework\authentication.py", line 201, in authenticate_credentials
    token = model.objects.select_related('user').get(key=key)
AttributeError: type object 'Token' has no attribute 'objects'

During handling of the above exception, another exception occurred:

Traceback (most recent call last):
  File "C:\Users\User\AppData\Local\Programs\Python\Python38-32\lib\site-packages\rest_framework\request.py", line 74, in wrap_attributeerrors
    yield
  File "C:\Users\User\AppData\Local\Programs\Python\Python38-32\lib\site-packages\rest_framework\request.py", line 227, in user
    self._authenticate()
  File "C:\Users\User\AppData\Local\Programs\Python\Python38-32\lib\site-packages\rest_framework\request.py", line 380, in _authenticate
    user_auth_tuple = authenticator.authenticate(self)
  File "C:\Users\User\AppData\Local\Programs\Python\Python38-32\lib\site-packages\rest_framework\authentication.py", line 196, in authenticate
    return self.authenticate_credentials(token)
  File "C:\Users\User\AppData\Local\Programs\Python\Python38-32\lib\site-packages\rest_framework\authentication.py", line 202, in authenticate_credentials
    except model.DoesNotExist:
AttributeError: type object 'Token' has no attribute 'DoesNotExist'

During handling of the above exception, another exception occurred:

Traceback (most recent call last):
  File "C:\Users\User\AppData\Local\Programs\Python\Python38-32\lib\site-packages\django\core\handlers\exception.py", line 47, in inner
    response = get_response(request)
  File "C:\Users\User\AppData\Local\Programs\Python\Python38-32\lib\site-packages\django\core\handlers\base.py", line 179, in _get_response
    response = wrapped_callback(request, *callback_args, **callback_kwargs)
  File "C:\Users\User\AppData\Local\Programs\Python\Python38-32\lib\site-packages\django\views\decorators\csrf.py", line 54, in wrapped_view
    return view_func(*args, **kwargs)
  File "C:\Users\User\AppData\Local\Programs\Python\Python38-32\lib\site-packages\django\views\decorators\csrf.py", line 54, in wrapped_view
    return view_func(*args, **kwargs)
  File "C:\Users\User\AppData\Local\Programs\Python\Python38-32\lib\site-packages\django\views\generic\base.py", line 70, in view
    return self.dispatch(request, *args, **kwargs)
  File "C:\Users\User\AppData\Local\Programs\Python\Python38-32\lib\site-packages\rest_framework\views.py", line 509, in dispatch
    response = self.handle_exception(exc)
  File "C:\Users\User\AppData\Local\Programs\Python\Python38-32\lib\site-packages\rest_framework\views.py", line 469, in handle_exception
    self.raise_uncaught_exception(exc)
  File "C:\Users\User\AppData\Local\Programs\Python\Python38-32\lib\site-packages\rest_framework\views.py", line 480, in raise_uncaught_exception
    raise exc
  File "C:\Users\User\AppData\Local\Programs\Python\Python38-32\lib\site-packages\rest_framework\views.py", line 497, in dispatch
    self.initial(request, *args, **kwargs)
  File "C:\Users\User\AppData\Local\Programs\Python\Python38-32\lib\site-packages\rest_framework\views.py", line 414, in initial
    self.perform_authentication(request)
  File "C:\Users\User\AppData\Local\Programs\Python\Python38-32\lib\site-packages\rest_framework\views.py", line 324, in perform_authentication
    request.user
  File "C:\Users\User\AppData\Local\Programs\Python\Python38-32\lib\site-packages\rest_framework\request.py", line 227, in user
    self._authenticate()
  File "C:\Users\User\AppData\Local\Programs\Python\Python38-32\lib\contextlib.py", line 131, in __exit__
    self.gen.throw(type, value, traceback)
  File "C:\Users\User\AppData\Local\Programs\Python\Python38-32\lib\site-packages\rest_framework\request.py", line 78, in wrap_attributeerrors
    raise exc.with_traceback(info[2])
  File "C:\Users\User\AppData\Local\Programs\Python\Python38-32\lib\site-packages\rest_framework\request.py", line 74, in wrap_attributeerrors
    yield
  File "C:\Users\User\AppData\Local\Programs\Python\Python38-32\lib\site-packages\rest_framework\request.py", line 227, in user
    self._authenticate()
  File "C:\Users\User\AppData\Local\Programs\Python\Python38-32\lib\site-packages\rest_framework\request.py", line 380, in _authenticate
    user_auth_tuple = authenticator.authenticate(self)
  File "C:\Users\User\AppData\Local\Programs\Python\Python38-32\lib\site-packages\rest_framework\authentication.py", line 196, in authenticate
    return self.authenticate_credentials(token)
  File "C:\Users\User\AppData\Local\Programs\Python\Python38-32\lib\site-packages\rest_framework\authentication.py", line 202, in authenticate_credentials
    except model.DoesNotExist:
rest_framework.request.WrappedAttributeError: type object 'Token' has no attribute 'DoesNotExist'
2021-11-02 11:50:11,177 Internal Server Error: /transaction_details/send/
Traceback (most recent call last):
  File "C:\Users\User\AppData\Local\Programs\Python\Python38-32\lib\site-packages\rest_framework\authentication.py", line 201, in authenticate_credentials
    token = model.objects.select_related('user').get(key=key)
AttributeError: type object 'Token' has no attribute 'objects'

During handling of the above exception, another exception occurred:

Traceback (most recent call last):
  File "C:\Users\User\AppData\Local\Programs\Python\Python38-32\lib\site-packages\rest_framework\request.py", line 74, in wrap_attributeerrors
    yield
  File "C:\Users\User\AppData\Local\Programs\Python\Python38-32\lib\site-packages\rest_framework\request.py", line 227, in user
    self._authenticate()
  File "C:\Users\User\AppData\Local\Programs\Python\Python38-32\lib\site-packages\rest_framework\request.py", line 380, in _authenticate
    user_auth_tuple = authenticator.authenticate(self)
  File "C:\Users\User\AppData\Local\Programs\Python\Python38-32\lib\site-packages\rest_framework\authentication.py", line 196, in authenticate
    return self.authenticate_credentials(token)
  File "C:\Users\User\AppData\Local\Programs\Python\Python38-32\lib\site-packages\rest_framework\authentication.py", line 202, in authenticate_credentials
    except model.DoesNotExist:
AttributeError: type object 'Token' has no attribute 'DoesNotExist'

During handling of the above exception, another exception occurred:

Traceback (most recent call last):
  File "C:\Users\User\AppData\Local\Programs\Python\Python38-32\lib\site-packages\django\core\handlers\exception.py", line 47, in inner
    response = get_response(request)
  File "C:\Users\User\AppData\Local\Programs\Python\Python38-32\lib\site-packages\django\core\handlers\base.py", line 179, in _get_response
    response = wrapped_callback(request, *callback_args, **callback_kwargs)
  File "C:\Users\User\AppData\Local\Programs\Python\Python38-32\lib\site-packages\django\views\decorators\csrf.py", line 54, in wrapped_view
    return view_func(*args, **kwargs)
  File "C:\Users\User\AppData\Local\Programs\Python\Python38-32\lib\site-packages\django\views\decorators\csrf.py", line 54, in wrapped_view
    return view_func(*args, **kwargs)
  File "C:\Users\User\AppData\Local\Programs\Python\Python38-32\lib\site-packages\django\views\generic\base.py", line 70, in view
    return self.dispatch(request, *args, **kwargs)
  File "C:\Users\User\AppData\Local\Programs\Python\Python38-32\lib\site-packages\rest_framework\views.py", line 509, in dispatch
    response = self.handle_exception(exc)
  File "C:\Users\User\AppData\Local\Programs\Python\Python38-32\lib\site-packages\rest_framework\views.py", line 469, in handle_exception
    self.raise_uncaught_exception(exc)
  File "C:\Users\User\AppData\Local\Programs\Python\Python38-32\lib\site-packages\rest_framework\views.py", line 480, in raise_uncaught_exception
    raise exc
  File "C:\Users\User\AppData\Local\Programs\Python\Python38-32\lib\site-packages\rest_framework\views.py", line 497, in dispatch
    self.initial(request, *args, **kwargs)
  File "C:\Users\User\AppData\Local\Programs\Python\Python38-32\lib\site-packages\rest_framework\views.py", line 414, in initial
    self.perform_authentication(request)
  File "C:\Users\User\AppData\Local\Programs\Python\Python38-32\lib\site-packages\rest_framework\views.py", line 324, in perform_authentication
    request.user
  File "C:\Users\User\AppData\Local\Programs\Python\Python38-32\lib\site-packages\rest_framework\request.py", line 227, in user
    self._authenticate()
  File "C:\Users\User\AppData\Local\Programs\Python\Python38-32\lib\contextlib.py", line 131, in __exit__
    self.gen.throw(type, value, traceback)
  File "C:\Users\User\AppData\Local\Programs\Python\Python38-32\lib\site-packages\rest_framework\request.py", line 78, in wrap_attributeerrors
    raise exc.with_traceback(info[2])
  File "C:\Users\User\AppData\Local\Programs\Python\Python38-32\lib\site-packages\rest_framework\request.py", line 74, in wrap_attributeerrors
    yield
  File "C:\Users\User\AppData\Local\Programs\Python\Python38-32\lib\site-packages\rest_framework\request.py", line 227, in user
    self._authenticate()
  File "C:\Users\User\AppData\Local\Programs\Python\Python38-32\lib\site-packages\rest_framework\request.py", line 380, in _authenticate
    user_auth_tuple = authenticator.authenticate(self)
  File "C:\Users\User\AppData\Local\Programs\Python\Python38-32\lib\site-packages\rest_framework\authentication.py", line 196, in authenticate
    return self.authenticate_credentials(token)
  File "C:\Users\User\AppData\Local\Programs\Python\Python38-32\lib\site-packages\rest_framework\authentication.py", line 202, in authenticate_credentials
    except model.DoesNotExist:
rest_framework.request.WrappedAttributeError: type object 'Token' has no attribute 'DoesNotExist'
2021-11-02 11:50:14,370 Internal Server Error: /transaction_details/send/
Traceback (most recent call last):
  File "C:\Users\User\AppData\Local\Programs\Python\Python38-32\lib\site-packages\rest_framework\authentication.py", line 201, in authenticate_credentials
    token = model.objects.select_related('user').get(key=key)
AttributeError: type object 'Token' has no attribute 'objects'

During handling of the above exception, another exception occurred:

Traceback (most recent call last):
  File "C:\Users\User\AppData\Local\Programs\Python\Python38-32\lib\site-packages\rest_framework\request.py", line 74, in wrap_attributeerrors
    yield
  File "C:\Users\User\AppData\Local\Programs\Python\Python38-32\lib\site-packages\rest_framework\request.py", line 227, in user
    self._authenticate()
  File "C:\Users\User\AppData\Local\Programs\Python\Python38-32\lib\site-packages\rest_framework\request.py", line 380, in _authenticate
    user_auth_tuple = authenticator.authenticate(self)
  File "C:\Users\User\AppData\Local\Programs\Python\Python38-32\lib\site-packages\rest_framework\authentication.py", line 196, in authenticate
    return self.authenticate_credentials(token)
  File "C:\Users\User\AppData\Local\Programs\Python\Python38-32\lib\site-packages\rest_framework\authentication.py", line 202, in authenticate_credentials
    except model.DoesNotExist:
AttributeError: type object 'Token' has no attribute 'DoesNotExist'

During handling of the above exception, another exception occurred:

Traceback (most recent call last):
  File "C:\Users\User\AppData\Local\Programs\Python\Python38-32\lib\site-packages\django\core\handlers\exception.py", line 47, in inner
    response = get_response(request)
  File "C:\Users\User\AppData\Local\Programs\Python\Python38-32\lib\site-packages\django\core\handlers\base.py", line 179, in _get_response
    response = wrapped_callback(request, *callback_args, **callback_kwargs)
  File "C:\Users\User\AppData\Local\Programs\Python\Python38-32\lib\site-packages\django\views\decorators\csrf.py", line 54, in wrapped_view
    return view_func(*args, **kwargs)
  File "C:\Users\User\AppData\Local\Programs\Python\Python38-32\lib\site-packages\django\views\decorators\csrf.py", line 54, in wrapped_view
    return view_func(*args, **kwargs)
  File "C:\Users\User\AppData\Local\Programs\Python\Python38-32\lib\site-packages\django\views\generic\base.py", line 70, in view
    return self.dispatch(request, *args, **kwargs)
  File "C:\Users\User\AppData\Local\Programs\Python\Python38-32\lib\site-packages\rest_framework\views.py", line 509, in dispatch
    response = self.handle_exception(exc)
  File "C:\Users\User\AppData\Local\Programs\Python\Python38-32\lib\site-packages\rest_framework\views.py", line 469, in handle_exception
    self.raise_uncaught_exception(exc)
  File "C:\Users\User\AppData\Local\Programs\Python\Python38-32\lib\site-packages\rest_framework\views.py", line 480, in raise_uncaught_exception
    raise exc
  File "C:\Users\User\AppData\Local\Programs\Python\Python38-32\lib\site-packages\rest_framework\views.py", line 497, in dispatch
    self.initial(request, *args, **kwargs)
  File "C:\Users\User\AppData\Local\Programs\Python\Python38-32\lib\site-packages\rest_framework\views.py", line 414, in initial
    self.perform_authentication(request)
  File "C:\Users\User\AppData\Local\Programs\Python\Python38-32\lib\site-packages\rest_framework\views.py", line 324, in perform_authentication
    request.user
  File "C:\Users\User\AppData\Local\Programs\Python\Python38-32\lib\site-packages\rest_framework\request.py", line 227, in user
    self._authenticate()
  File "C:\Users\User\AppData\Local\Programs\Python\Python38-32\lib\contextlib.py", line 131, in __exit__
    self.gen.throw(type, value, traceback)
  File "C:\Users\User\AppData\Local\Programs\Python\Python38-32\lib\site-packages\rest_framework\request.py", line 78, in wrap_attributeerrors
    raise exc.with_traceback(info[2])
  File "C:\Users\User\AppData\Local\Programs\Python\Python38-32\lib\site-packages\rest_framework\request.py", line 74, in wrap_attributeerrors
    yield
  File "C:\Users\User\AppData\Local\Programs\Python\Python38-32\lib\site-packages\rest_framework\request.py", line 227, in user
    self._authenticate()
  File "C:\Users\User\AppData\Local\Programs\Python\Python38-32\lib\site-packages\rest_framework\request.py", line 380, in _authenticate
    user_auth_tuple = authenticator.authenticate(self)
  File "C:\Users\User\AppData\Local\Programs\Python\Python38-32\lib\site-packages\rest_framework\authentication.py", line 196, in authenticate
    return self.authenticate_credentials(token)
  File "C:\Users\User\AppData\Local\Programs\Python\Python38-32\lib\site-packages\rest_framework\authentication.py", line 202, in authenticate_credentials
    except model.DoesNotExist:
rest_framework.request.WrappedAttributeError: type object 'Token' has no attribute 'DoesNotExist'
2021-11-02 11:51:02,486 Internal Server Error: /transaction_details/send/
Traceback (most recent call last):
  File "C:\Users\User\AppData\Local\Programs\Python\Python38-32\lib\site-packages\rest_framework\authentication.py", line 201, in authenticate_credentials
    token = model.objects.select_related('user').get(key=key)
AttributeError: type object 'Token' has no attribute 'objects'

During handling of the above exception, another exception occurred:

Traceback (most recent call last):
  File "C:\Users\User\AppData\Local\Programs\Python\Python38-32\lib\site-packages\rest_framework\request.py", line 74, in wrap_attributeerrors
    yield
  File "C:\Users\User\AppData\Local\Programs\Python\Python38-32\lib\site-packages\rest_framework\request.py", line 227, in user
    self._authenticate()
  File "C:\Users\User\AppData\Local\Programs\Python\Python38-32\lib\site-packages\rest_framework\request.py", line 380, in _authenticate
    user_auth_tuple = authenticator.authenticate(self)
  File "C:\Users\User\AppData\Local\Programs\Python\Python38-32\lib\site-packages\rest_framework\authentication.py", line 196, in authenticate
    return self.authenticate_credentials(token)
  File "C:\Users\User\AppData\Local\Programs\Python\Python38-32\lib\site-packages\rest_framework\authentication.py", line 202, in authenticate_credentials
    except model.DoesNotExist:
AttributeError: type object 'Token' has no attribute 'DoesNotExist'

During handling of the above exception, another exception occurred:

Traceback (most recent call last):
  File "C:\Users\User\AppData\Local\Programs\Python\Python38-32\lib\site-packages\django\core\handlers\exception.py", line 47, in inner
    response = get_response(request)
  File "C:\Users\User\AppData\Local\Programs\Python\Python38-32\lib\site-packages\django\core\handlers\base.py", line 179, in _get_response
    response = wrapped_callback(request, *callback_args, **callback_kwargs)
  File "C:\Users\User\AppData\Local\Programs\Python\Python38-32\lib\site-packages\django\views\decorators\csrf.py", line 54, in wrapped_view
    return view_func(*args, **kwargs)
  File "C:\Users\User\AppData\Local\Programs\Python\Python38-32\lib\site-packages\django\views\decorators\csrf.py", line 54, in wrapped_view
    return view_func(*args, **kwargs)
  File "C:\Users\User\AppData\Local\Programs\Python\Python38-32\lib\site-packages\django\views\generic\base.py", line 70, in view
    return self.dispatch(request, *args, **kwargs)
  File "C:\Users\User\AppData\Local\Programs\Python\Python38-32\lib\site-packages\rest_framework\views.py", line 509, in dispatch
    response = self.handle_exception(exc)
  File "C:\Users\User\AppData\Local\Programs\Python\Python38-32\lib\site-packages\rest_framework\views.py", line 469, in handle_exception
    self.raise_uncaught_exception(exc)
  File "C:\Users\User\AppData\Local\Programs\Python\Python38-32\lib\site-packages\rest_framework\views.py", line 480, in raise_uncaught_exception
    raise exc
  File "C:\Users\User\AppData\Local\Programs\Python\Python38-32\lib\site-packages\rest_framework\views.py", line 497, in dispatch
    self.initial(request, *args, **kwargs)
  File "C:\Users\User\AppData\Local\Programs\Python\Python38-32\lib\site-packages\rest_framework\views.py", line 414, in initial
    self.perform_authentication(request)
  File "C:\Users\User\AppData\Local\Programs\Python\Python38-32\lib\site-packages\rest_framework\views.py", line 324, in perform_authentication
    request.user
  File "C:\Users\User\AppData\Local\Programs\Python\Python38-32\lib\site-packages\rest_framework\request.py", line 227, in user
    self._authenticate()
  File "C:\Users\User\AppData\Local\Programs\Python\Python38-32\lib\contextlib.py", line 131, in __exit__
    self.gen.throw(type, value, traceback)
  File "C:\Users\User\AppData\Local\Programs\Python\Python38-32\lib\site-packages\rest_framework\request.py", line 78, in wrap_attributeerrors
    raise exc.with_traceback(info[2])
  File "C:\Users\User\AppData\Local\Programs\Python\Python38-32\lib\site-packages\rest_framework\request.py", line 74, in wrap_attributeerrors
    yield
  File "C:\Users\User\AppData\Local\Programs\Python\Python38-32\lib\site-packages\rest_framework\request.py", line 227, in user
    self._authenticate()
  File "C:\Users\User\AppData\Local\Programs\Python\Python38-32\lib\site-packages\rest_framework\request.py", line 380, in _authenticate
    user_auth_tuple = authenticator.authenticate(self)
  File "C:\Users\User\AppData\Local\Programs\Python\Python38-32\lib\site-packages\rest_framework\authentication.py", line 196, in authenticate
    return self.authenticate_credentials(token)
  File "C:\Users\User\AppData\Local\Programs\Python\Python38-32\lib\site-packages\rest_framework\authentication.py", line 202, in authenticate_credentials
    except model.DoesNotExist:
rest_framework.request.WrappedAttributeError: type object 'Token' has no attribute 'DoesNotExist'
2021-11-02 11:53:37,192 C:\ES_POST_API\es_post_api\api\views.py changed, reloading.
2021-11-02 11:53:56,970 Internal Server Error: /transaction_details/send/
Traceback (most recent call last):
  File "C:\Users\User\AppData\Local\Programs\Python\Python38-32\lib\site-packages\rest_framework\authentication.py", line 201, in authenticate_credentials
    token = model.objects.select_related('user').get(key=key)
AttributeError: type object 'Token' has no attribute 'objects'

During handling of the above exception, another exception occurred:

Traceback (most recent call last):
  File "C:\Users\User\AppData\Local\Programs\Python\Python38-32\lib\site-packages\rest_framework\request.py", line 74, in wrap_attributeerrors
    yield
  File "C:\Users\User\AppData\Local\Programs\Python\Python38-32\lib\site-packages\rest_framework\request.py", line 227, in user
    self._authenticate()
  File "C:\Users\User\AppData\Local\Programs\Python\Python38-32\lib\site-packages\rest_framework\request.py", line 380, in _authenticate
    user_auth_tuple = authenticator.authenticate(self)
  File "C:\Users\User\AppData\Local\Programs\Python\Python38-32\lib\site-packages\rest_framework\authentication.py", line 196, in authenticate
    return self.authenticate_credentials(token)
  File "C:\Users\User\AppData\Local\Programs\Python\Python38-32\lib\site-packages\rest_framework\authentication.py", line 202, in authenticate_credentials
    except model.DoesNotExist:
AttributeError: type object 'Token' has no attribute 'DoesNotExist'

During handling of the above exception, another exception occurred:

Traceback (most recent call last):
  File "C:\Users\User\AppData\Local\Programs\Python\Python38-32\lib\site-packages\django\core\handlers\exception.py", line 47, in inner
    response = get_response(request)
  File "C:\Users\User\AppData\Local\Programs\Python\Python38-32\lib\site-packages\django\core\handlers\base.py", line 179, in _get_response
    response = wrapped_callback(request, *callback_args, **callback_kwargs)
  File "C:\Users\User\AppData\Local\Programs\Python\Python38-32\lib\site-packages\django\views\decorators\csrf.py", line 54, in wrapped_view
    return view_func(*args, **kwargs)
  File "C:\Users\User\AppData\Local\Programs\Python\Python38-32\lib\site-packages\django\views\decorators\csrf.py", line 54, in wrapped_view
    return view_func(*args, **kwargs)
  File "C:\Users\User\AppData\Local\Programs\Python\Python38-32\lib\site-packages\django\views\generic\base.py", line 70, in view
    return self.dispatch(request, *args, **kwargs)
  File "C:\Users\User\AppData\Local\Programs\Python\Python38-32\lib\site-packages\rest_framework\views.py", line 509, in dispatch
    response = self.handle_exception(exc)
  File "C:\Users\User\AppData\Local\Programs\Python\Python38-32\lib\site-packages\rest_framework\views.py", line 469, in handle_exception
    self.raise_uncaught_exception(exc)
  File "C:\Users\User\AppData\Local\Programs\Python\Python38-32\lib\site-packages\rest_framework\views.py", line 480, in raise_uncaught_exception
    raise exc
  File "C:\Users\User\AppData\Local\Programs\Python\Python38-32\lib\site-packages\rest_framework\views.py", line 497, in dispatch
    self.initial(request, *args, **kwargs)
  File "C:\Users\User\AppData\Local\Programs\Python\Python38-32\lib\site-packages\rest_framework\views.py", line 414, in initial
    self.perform_authentication(request)
  File "C:\Users\User\AppData\Local\Programs\Python\Python38-32\lib\site-packages\rest_framework\views.py", line 324, in perform_authentication
    request.user
  File "C:\Users\User\AppData\Local\Programs\Python\Python38-32\lib\site-packages\rest_framework\request.py", line 227, in user
    self._authenticate()
  File "C:\Users\User\AppData\Local\Programs\Python\Python38-32\lib\contextlib.py", line 131, in __exit__
    self.gen.throw(type, value, traceback)
  File "C:\Users\User\AppData\Local\Programs\Python\Python38-32\lib\site-packages\rest_framework\request.py", line 78, in wrap_attributeerrors
    raise exc.with_traceback(info[2])
  File "C:\Users\User\AppData\Local\Programs\Python\Python38-32\lib\site-packages\rest_framework\request.py", line 74, in wrap_attributeerrors
    yield
  File "C:\Users\User\AppData\Local\Programs\Python\Python38-32\lib\site-packages\rest_framework\request.py", line 227, in user
    self._authenticate()
  File "C:\Users\User\AppData\Local\Programs\Python\Python38-32\lib\site-packages\rest_framework\request.py", line 380, in _authenticate
    user_auth_tuple = authenticator.authenticate(self)
  File "C:\Users\User\AppData\Local\Programs\Python\Python38-32\lib\site-packages\rest_framework\authentication.py", line 196, in authenticate
    return self.authenticate_credentials(token)
  File "C:\Users\User\AppData\Local\Programs\Python\Python38-32\lib\site-packages\rest_framework\authentication.py", line 202, in authenticate_credentials
    except model.DoesNotExist:
rest_framework.request.WrappedAttributeError: type object 'Token' has no attribute 'DoesNotExist'
2021-11-02 11:54:10,119 Internal Server Error: /transaction_details/send/
Traceback (most recent call last):
  File "C:\Users\User\AppData\Local\Programs\Python\Python38-32\lib\site-packages\rest_framework\authentication.py", line 201, in authenticate_credentials
    token = model.objects.select_related('user').get(key=key)
AttributeError: type object 'Token' has no attribute 'objects'

During handling of the above exception, another exception occurred:

Traceback (most recent call last):
  File "C:\Users\User\AppData\Local\Programs\Python\Python38-32\lib\site-packages\rest_framework\request.py", line 74, in wrap_attributeerrors
    yield
  File "C:\Users\User\AppData\Local\Programs\Python\Python38-32\lib\site-packages\rest_framework\request.py", line 227, in user
    self._authenticate()
  File "C:\Users\User\AppData\Local\Programs\Python\Python38-32\lib\site-packages\rest_framework\request.py", line 380, in _authenticate
    user_auth_tuple = authenticator.authenticate(self)
  File "C:\Users\User\AppData\Local\Programs\Python\Python38-32\lib\site-packages\rest_framework\authentication.py", line 196, in authenticate
    return self.authenticate_credentials(token)
  File "C:\Users\User\AppData\Local\Programs\Python\Python38-32\lib\site-packages\rest_framework\authentication.py", line 202, in authenticate_credentials
    except model.DoesNotExist:
AttributeError: type object 'Token' has no attribute 'DoesNotExist'

During handling of the above exception, another exception occurred:

Traceback (most recent call last):
  File "C:\Users\User\AppData\Local\Programs\Python\Python38-32\lib\site-packages\django\core\handlers\exception.py", line 47, in inner
    response = get_response(request)
  File "C:\Users\User\AppData\Local\Programs\Python\Python38-32\lib\site-packages\django\core\handlers\base.py", line 179, in _get_response
    response = wrapped_callback(request, *callback_args, **callback_kwargs)
  File "C:\Users\User\AppData\Local\Programs\Python\Python38-32\lib\site-packages\django\views\decorators\csrf.py", line 54, in wrapped_view
    return view_func(*args, **kwargs)
  File "C:\Users\User\AppData\Local\Programs\Python\Python38-32\lib\site-packages\django\views\decorators\csrf.py", line 54, in wrapped_view
    return view_func(*args, **kwargs)
  File "C:\Users\User\AppData\Local\Programs\Python\Python38-32\lib\site-packages\django\views\generic\base.py", line 70, in view
    return self.dispatch(request, *args, **kwargs)
  File "C:\Users\User\AppData\Local\Programs\Python\Python38-32\lib\site-packages\rest_framework\views.py", line 509, in dispatch
    response = self.handle_exception(exc)
  File "C:\Users\User\AppData\Local\Programs\Python\Python38-32\lib\site-packages\rest_framework\views.py", line 469, in handle_exception
    self.raise_uncaught_exception(exc)
  File "C:\Users\User\AppData\Local\Programs\Python\Python38-32\lib\site-packages\rest_framework\views.py", line 480, in raise_uncaught_exception
    raise exc
  File "C:\Users\User\AppData\Local\Programs\Python\Python38-32\lib\site-packages\rest_framework\views.py", line 497, in dispatch
    self.initial(request, *args, **kwargs)
  File "C:\Users\User\AppData\Local\Programs\Python\Python38-32\lib\site-packages\rest_framework\views.py", line 414, in initial
    self.perform_authentication(request)
  File "C:\Users\User\AppData\Local\Programs\Python\Python38-32\lib\site-packages\rest_framework\views.py", line 324, in perform_authentication
    request.user
  File "C:\Users\User\AppData\Local\Programs\Python\Python38-32\lib\site-packages\rest_framework\request.py", line 227, in user
    self._authenticate()
  File "C:\Users\User\AppData\Local\Programs\Python\Python38-32\lib\contextlib.py", line 131, in __exit__
    self.gen.throw(type, value, traceback)
  File "C:\Users\User\AppData\Local\Programs\Python\Python38-32\lib\site-packages\rest_framework\request.py", line 78, in wrap_attributeerrors
    raise exc.with_traceback(info[2])
  File "C:\Users\User\AppData\Local\Programs\Python\Python38-32\lib\site-packages\rest_framework\request.py", line 74, in wrap_attributeerrors
    yield
  File "C:\Users\User\AppData\Local\Programs\Python\Python38-32\lib\site-packages\rest_framework\request.py", line 227, in user
    self._authenticate()
  File "C:\Users\User\AppData\Local\Programs\Python\Python38-32\lib\site-packages\rest_framework\request.py", line 380, in _authenticate
    user_auth_tuple = authenticator.authenticate(self)
  File "C:\Users\User\AppData\Local\Programs\Python\Python38-32\lib\site-packages\rest_framework\authentication.py", line 196, in authenticate
    return self.authenticate_credentials(token)
  File "C:\Users\User\AppData\Local\Programs\Python\Python38-32\lib\site-packages\rest_framework\authentication.py", line 202, in authenticate_credentials
    except model.DoesNotExist:
rest_framework.request.WrappedAttributeError: type object 'Token' has no attribute 'DoesNotExist'
2021-11-02 11:54:33,705 C:\ES_POST_API\es_post_api\api\views.py changed, reloading.
2021-11-02 11:56:21,540 Internal Server Error: /transaction_details/send/
Traceback (most recent call last):
  File "C:\Users\User\AppData\Local\Programs\Python\Python38-32\lib\site-packages\rest_framework\authentication.py", line 201, in authenticate_credentials
    token = model.objects.select_related('user').get(key=key)
AttributeError: type object 'Token' has no attribute 'objects'

During handling of the above exception, another exception occurred:

Traceback (most recent call last):
  File "C:\Users\User\AppData\Local\Programs\Python\Python38-32\lib\site-packages\rest_framework\request.py", line 74, in wrap_attributeerrors
    yield
  File "C:\Users\User\AppData\Local\Programs\Python\Python38-32\lib\site-packages\rest_framework\request.py", line 227, in user
    self._authenticate()
  File "C:\Users\User\AppData\Local\Programs\Python\Python38-32\lib\site-packages\rest_framework\request.py", line 380, in _authenticate
    user_auth_tuple = authenticator.authenticate(self)
  File "C:\Users\User\AppData\Local\Programs\Python\Python38-32\lib\site-packages\rest_framework\authentication.py", line 196, in authenticate
    return self.authenticate_credentials(token)
  File "C:\Users\User\AppData\Local\Programs\Python\Python38-32\lib\site-packages\rest_framework\authentication.py", line 202, in authenticate_credentials
    except model.DoesNotExist:
AttributeError: type object 'Token' has no attribute 'DoesNotExist'

During handling of the above exception, another exception occurred:

Traceback (most recent call last):
  File "C:\Users\User\AppData\Local\Programs\Python\Python38-32\lib\site-packages\django\core\handlers\exception.py", line 47, in inner
    response = get_response(request)
  File "C:\Users\User\AppData\Local\Programs\Python\Python38-32\lib\site-packages\django\core\handlers\base.py", line 179, in _get_response
    response = wrapped_callback(request, *callback_args, **callback_kwargs)
  File "C:\Users\User\AppData\Local\Programs\Python\Python38-32\lib\site-packages\django\views\decorators\csrf.py", line 54, in wrapped_view
    return view_func(*args, **kwargs)
  File "C:\Users\User\AppData\Local\Programs\Python\Python38-32\lib\site-packages\django\views\decorators\csrf.py", line 54, in wrapped_view
    return view_func(*args, **kwargs)
  File "C:\Users\User\AppData\Local\Programs\Python\Python38-32\lib\site-packages\django\views\generic\base.py", line 70, in view
    return self.dispatch(request, *args, **kwargs)
  File "C:\Users\User\AppData\Local\Programs\Python\Python38-32\lib\site-packages\rest_framework\views.py", line 509, in dispatch
    response = self.handle_exception(exc)
  File "C:\Users\User\AppData\Local\Programs\Python\Python38-32\lib\site-packages\rest_framework\views.py", line 469, in handle_exception
    self.raise_uncaught_exception(exc)
  File "C:\Users\User\AppData\Local\Programs\Python\Python38-32\lib\site-packages\rest_framework\views.py", line 480, in raise_uncaught_exception
    raise exc
  File "C:\Users\User\AppData\Local\Programs\Python\Python38-32\lib\site-packages\rest_framework\views.py", line 497, in dispatch
    self.initial(request, *args, **kwargs)
  File "C:\Users\User\AppData\Local\Programs\Python\Python38-32\lib\site-packages\rest_framework\views.py", line 414, in initial
    self.perform_authentication(request)
  File "C:\Users\User\AppData\Local\Programs\Python\Python38-32\lib\site-packages\rest_framework\views.py", line 324, in perform_authentication
    request.user
  File "C:\Users\User\AppData\Local\Programs\Python\Python38-32\lib\site-packages\rest_framework\request.py", line 227, in user
    self._authenticate()
  File "C:\Users\User\AppData\Local\Programs\Python\Python38-32\lib\contextlib.py", line 131, in __exit__
    self.gen.throw(type, value, traceback)
  File "C:\Users\User\AppData\Local\Programs\Python\Python38-32\lib\site-packages\rest_framework\request.py", line 78, in wrap_attributeerrors
    raise exc.with_traceback(info[2])
  File "C:\Users\User\AppData\Local\Programs\Python\Python38-32\lib\site-packages\rest_framework\request.py", line 74, in wrap_attributeerrors
    yield
  File "C:\Users\User\AppData\Local\Programs\Python\Python38-32\lib\site-packages\rest_framework\request.py", line 227, in user
    self._authenticate()
  File "C:\Users\User\AppData\Local\Programs\Python\Python38-32\lib\site-packages\rest_framework\request.py", line 380, in _authenticate
    user_auth_tuple = authenticator.authenticate(self)
  File "C:\Users\User\AppData\Local\Programs\Python\Python38-32\lib\site-packages\rest_framework\authentication.py", line 196, in authenticate
    return self.authenticate_credentials(token)
  File "C:\Users\User\AppData\Local\Programs\Python\Python38-32\lib\site-packages\rest_framework\authentication.py", line 202, in authenticate_credentials
    except model.DoesNotExist:
rest_framework.request.WrappedAttributeError: type object 'Token' has no attribute 'DoesNotExist'
2021-11-02 11:59:28,177 Internal Server Error: /transaction_details/send/
Traceback (most recent call last):
  File "C:\Users\User\AppData\Local\Programs\Python\Python38-32\lib\site-packages\rest_framework\authentication.py", line 201, in authenticate_credentials
    token = model.objects.select_related('user').get(key=key)
AttributeError: type object 'Token' has no attribute 'objects'

During handling of the above exception, another exception occurred:

Traceback (most recent call last):
  File "C:\Users\User\AppData\Local\Programs\Python\Python38-32\lib\site-packages\rest_framework\request.py", line 74, in wrap_attributeerrors
    yield
  File "C:\Users\User\AppData\Local\Programs\Python\Python38-32\lib\site-packages\rest_framework\request.py", line 227, in user
    self._authenticate()
  File "C:\Users\User\AppData\Local\Programs\Python\Python38-32\lib\site-packages\rest_framework\request.py", line 380, in _authenticate
    user_auth_tuple = authenticator.authenticate(self)
  File "C:\Users\User\AppData\Local\Programs\Python\Python38-32\lib\site-packages\rest_framework\authentication.py", line 196, in authenticate
    return self.authenticate_credentials(token)
  File "C:\Users\User\AppData\Local\Programs\Python\Python38-32\lib\site-packages\rest_framework\authentication.py", line 202, in authenticate_credentials
    except model.DoesNotExist:
AttributeError: type object 'Token' has no attribute 'DoesNotExist'

During handling of the above exception, another exception occurred:

Traceback (most recent call last):
  File "C:\Users\User\AppData\Local\Programs\Python\Python38-32\lib\site-packages\django\core\handlers\exception.py", line 47, in inner
    response = get_response(request)
  File "C:\Users\User\AppData\Local\Programs\Python\Python38-32\lib\site-packages\django\core\handlers\base.py", line 179, in _get_response
    response = wrapped_callback(request, *callback_args, **callback_kwargs)
  File "C:\Users\User\AppData\Local\Programs\Python\Python38-32\lib\site-packages\django\views\decorators\csrf.py", line 54, in wrapped_view
    return view_func(*args, **kwargs)
  File "C:\Users\User\AppData\Local\Programs\Python\Python38-32\lib\site-packages\django\views\decorators\csrf.py", line 54, in wrapped_view
    return view_func(*args, **kwargs)
  File "C:\Users\User\AppData\Local\Programs\Python\Python38-32\lib\site-packages\django\views\generic\base.py", line 70, in view
    return self.dispatch(request, *args, **kwargs)
  File "C:\Users\User\AppData\Local\Programs\Python\Python38-32\lib\site-packages\rest_framework\views.py", line 509, in dispatch
    response = self.handle_exception(exc)
  File "C:\Users\User\AppData\Local\Programs\Python\Python38-32\lib\site-packages\rest_framework\views.py", line 469, in handle_exception
    self.raise_uncaught_exception(exc)
  File "C:\Users\User\AppData\Local\Programs\Python\Python38-32\lib\site-packages\rest_framework\views.py", line 480, in raise_uncaught_exception
    raise exc
  File "C:\Users\User\AppData\Local\Programs\Python\Python38-32\lib\site-packages\rest_framework\views.py", line 497, in dispatch
    self.initial(request, *args, **kwargs)
  File "C:\Users\User\AppData\Local\Programs\Python\Python38-32\lib\site-packages\rest_framework\views.py", line 414, in initial
    self.perform_authentication(request)
  File "C:\Users\User\AppData\Local\Programs\Python\Python38-32\lib\site-packages\rest_framework\views.py", line 324, in perform_authentication
    request.user
  File "C:\Users\User\AppData\Local\Programs\Python\Python38-32\lib\site-packages\rest_framework\request.py", line 227, in user
    self._authenticate()
  File "C:\Users\User\AppData\Local\Programs\Python\Python38-32\lib\contextlib.py", line 131, in __exit__
    self.gen.throw(type, value, traceback)
  File "C:\Users\User\AppData\Local\Programs\Python\Python38-32\lib\site-packages\rest_framework\request.py", line 78, in wrap_attributeerrors
    raise exc.with_traceback(info[2])
  File "C:\Users\User\AppData\Local\Programs\Python\Python38-32\lib\site-packages\rest_framework\request.py", line 74, in wrap_attributeerrors
    yield
  File "C:\Users\User\AppData\Local\Programs\Python\Python38-32\lib\site-packages\rest_framework\request.py", line 227, in user
    self._authenticate()
  File "C:\Users\User\AppData\Local\Programs\Python\Python38-32\lib\site-packages\rest_framework\request.py", line 380, in _authenticate
    user_auth_tuple = authenticator.authenticate(self)
  File "C:\Users\User\AppData\Local\Programs\Python\Python38-32\lib\site-packages\rest_framework\authentication.py", line 196, in authenticate
    return self.authenticate_credentials(token)
  File "C:\Users\User\AppData\Local\Programs\Python\Python38-32\lib\site-packages\rest_framework\authentication.py", line 202, in authenticate_credentials
    except model.DoesNotExist:
rest_framework.request.WrappedAttributeError: type object 'Token' has no attribute 'DoesNotExist'
2021-11-02 12:10:27,178 b'[{"transaction_id":["transaction with this transaction id already exists."]}]'
2021-11-02 12:10:27,206 Bad Request: /transaction_details/send/
